Workbook

Sheet Compare
A1: # | B1: Constraint | D1: Fuel Cost | H1: Startup Up Cost | I1: Shutdown Cost | J1: Total Cost
B2: myProject | C2: myUC | D2: Quadratic | E2: Linear | F2: No Load | G2: Piecewise
A3: 1 | B3: use_initial_condition con_power_balance con_capacity_upper con_capacity_lower con_startup_shutdown_logic | C3: consInit consUC | D3: 0 | E3: 3444016.2 | F3: 411849.85 | G3: 0 | H3: 14016 | I3: 0 | J3: 3869882.1
A4: 2 | B4: use_initial_condition con_power_balance con_capacity_upper con_capacity_lower con_startup_shutdown_logic con_minimum_up_time con_minimum_down_time | C4: consInit consUC consMUTMDT | D4: 0 | E4: 3454898.3 | F4: 418325.47 | G4: 0 | H4: 8304 | I4: 0 | J4: 3881527.8
C5: consUC consMUTMDT consBasicRamp | D5: 0 | E5: 345585436 | F5: 418325.47 | G5: 0 | H5: 8304 | I5: 0 | J5: 3882483.8
A6: 3 | B6: use_initial_condition con_power_balance con_capacity_upper con_capacity_lower con_startup_shutdown_logic con_minimum_up_time con_minimum_down_time con_ramp_up con_ramp_down | C6: consUC consMUTMDT consBasicRamp consInit | D6: 0 | E6: 3452429.4 | F6: 454586.54 | G6: 0 | H6: 0 | I6: 0 | J6: 3907015.9
A7: 4 | B7: use_initial_condition con_power_balance con_capacity_upper con_capacity_lower con_startup_shutdown_logic con_minimum_up_time con_minimum_down_time con_ramp_up con_ramp_down con_n1_spinning_reserve | C7: consUC consMUTMDT consBasicRamp consSRContingency consInit | D7: 0 | E7: 3452429.4 | F7: 514953.88 | G7: 0 | H7: 61840 | I7: 0 | J7: 4029223.2
C8: consUC consMUTMDT consBasicRamp consSRContingency | D8: 0 | E8: 3440079 | F8: 514953.88 | G8: 0 | H8: 61840 | I8: 0 | J8: 4016872.8
C9: consUC consMUTMDT consBasicRamp consSRPower consReserveJawaBali | D9: 0 | E9: 3549736 | F9: 606755.37 | G9: 0 | H9: 61840 | I9: 0 | J9: 4218331.4
C10: consUC consMUTMDT consBasicRamp consReserveJawaBali | D10: 0 | E10: 3549736 | F10: 606755.37 | G10: 0 | H10: 61840 | I10: 0 | J10: 4218331.4
A11: 5 | B11: use_initial_condition con_power_balance con_capacity_upper con_capacity_lower con_startup_shutdown_logic con_minimum_up_time con_minimum_down_time con_ramp_up con_ramp_down con_n1_spinning_reserve con_dynamic_frequency_security | C11: consUC consMUTMDT consBasicRamp consSRContingency consWorstCaseInertia consInit | D11: 0 | E11: 3965848.2 | F11: 550301.39 | G11: 0 | H11: 0 | I11: 0 | J11: 4516149.6
A12: 6 | B12: use_initial_condition con_power_balance con_capacity_upper con_capacity_lower con_startup_shutdown_logic con_minimum_up_time con_minimum_down_time con_ramp_up con_ramp_down con_n1_spinning_reserve con_steady_primary_frequency | C12: consUC consMUTMDT consBasicRamp consSRContingency consSteadyPrimFreq consInit | D12: 0 | E12: 3752693.7 | F12: 551968.11 | G12: 0 | H12: 0 | I12: 0 | J12: 4304661.8
B13: use_initial_condition con_power_balance con_capacity_upper con_capacity_lower con_startup_shutdown_logic con_minimum_up_time con_minimum_down_time con_ramp_up con_ramp_down con_n1_spinning_reserve con_steady_primary_frequency | D13: 0 | E13: 3452429.4 | F13: 514953.88 | G13: 0 | H13: 61840 | I13: 0 | J13: 4029223.2
A14: 8 | C14: consUC consMUTMDT consBasicRamp consReserveJawaBali consSteadyPrimFreq | D14: 0 | E14: 3695939.3 | F14: 606755.37 | G14: 0 | H14: 61840 | I14: 0 | J14: 4364534.7
A15: 9 | C15: consUC consMUTMDT consBasicRamp consReserveJawaBali consWorstCaseInertia | D15: 0 | E15: 3906762.6 | F15: 641975.75 | G15: 0 | H15: 0 | I15: 0 | J15: 4548738.3
A16: 7 | B16: use_initial_condition con_power_balance con_capacity_upper con_capacity_lower con_startup_shutdown_logic con_minimum_up_time con_minimum_down_time con_ramp_up con_ramp_down con_n1_spinning_reserve con_battery | C16: consUC consMUTMDT consBasicRamp consSRContingency consBattery consInit | D16: 0 | E16: 3506628 | F16: 507544.53 | G16: 0 | H16: 5712 | J16: 4019884.5
B17: use_initial_condition con_power_balance con_capacity_upper con_capacity_lower con_startup_shutdown_logic con_minimum_up_time con_minimum_down_time con_ramp_up con_ramp_down con_n1_spinning_reserve con_battery con_WT con_curtailment | D17: 0 | E17: 3226209.5 | F17: 487589.45 | G17: 0 | H17: 2592 | I17: 0 | J17: 3716390.9
B18: use_initial_condition con_power_balance con_capacity_upper con_capacity_lower con_startup_shutdown_logic con_minimum_up_time con_minimum_down_time con_ramp_up con_ramp_down con_n1_spinning_reserve con_WT con_curtailment | D18: 0 | E18: 3230864.4 | F18: 487589.45 | G18: 0 | H18: 2592 | I18: 0 | J18: 3721045.8

Sheet Sheet1
A1: #1
A2: consInit + consUC
A4: Objective | E4: UC Status | AE4: Dispatch | BF4: System Inertia | BO4: Spinning Reserve | CP4: Primary Reserve
A5: Fuel Cost | B5: Quadratic | C5: 0 | E5: Gen | F5: Hour | AE5: Gen | AG5: Hour | BF5: Hour | BG5: Hsys | BI5: Hour | BJ5: Hsys | BL5: Hour | BM5: Hsys | BO5: Gen | BQ5: Hour | CP5: Gen | CR5: Hour
B6: Linear | C6: 3444016.2 | F6: 1 | G6: 2 | H6: 3 | I6: 4 | J6: 5 | K6: 6 | L6: 7 | M6: 8 | N6: 9 | O6: 10 | P6: 11 | Q6: 12 | R6: 13 | S6: 14 | T6: 15 | U6: 16 | V6: 17 | W6: 18 | X6: 19 | Y6: 20 | Z6: 21 | AA6: 22 | AB6: 23 | AC6: 24 | AG6: 1 | AH6: 2 | AI6: 3 | AJ6: 4 | AK6: 5 | AL6: 6 | AM6: 7 | AN6: 8 | AO6: 9 | AP6: 10 | AQ6: 11 | AR6: 12 | AS6: 13 | AT6: 14 | AU6: 15 | AV6: 16 | AW6: 17 | AX6: 18 | AY6: 19 | AZ6: 20 | BA6: 21 | BB6: 22 | BC6: 23 | BD6: 24 | BF6: 1 | BG6: 505.5 | BI6: 11 | BJ6: 518.46 | BL6: 21 | BM6: 534.06 | BQ6: 1 | BR6: 2 | BS6: 3 | BT6: 4 | BU6: 5 | BV6: 6 | BW6: 7 | BX6: 8 | BY6: 9 | BZ6: 10 | CA6: 11 | CB6: 12 | CC6: 13 | CD6: 14 | CE6: 15 | CF6: 16 | CG6: 17 | CH6: 18 | CI6: 19 | CJ6: 20 | CK6: 21 | CL6: 22 | CM6: 23 | CN6: 24 | CR6: 1 | CS6: 2 | CT6: 3 | CU6: 4 | CV6: 5 | CW6: 6 | CX6: 7 | CY6: 8 | CZ6: 9 | DA6: 10 | DB6: 11 | DC6: 12 | DD6: 13 | DE6: 14 | DF6: 15 | DG6: 16 | DH6: 17 | DI6: 18 | DJ6: 19 | DK6: 20 | DL6: 21 | DM6: 22 | DN6: 23 | DO6: 24
B7: No Load | C7: 411849.85 | E7: G 01 | F7: 1 | G7: 1 | H7: 1 | I7: 1 | J7: 1 | K7: 1 | L7: 1 | M7: 1 | N7: 1 | O7: 1 | P7: 1 | Q7: 1 | R7: 1 | S7: 1 | T7: 1 | U7: 1 | V7: 1 | W7: 1 | X7: 1 | Y7: 1 | Z7: 1 | AA7: 1 | AB7: 1 | AC7: 1 | AE7: G 01 | AF7: PLTU 1 | AG7: 1176 | AH7: 1176 | AI7: 1176 | AJ7: 1176 | AK7: 1080.3834 | AL7: 1176 | AM7: 1176 | AN7: 1176 | AO7: 1176 | AP7: 1176 | AQ7: 1176 | AR7: 1176 | AS7: 1176 | AT7: 1176 | AU7: 1176 | AV7: 1176 | AW7: 1176 | AX7: 1176 | AY7: 1176 | AZ7: 1176 | BA7: 1176 | BB7: 1176 | BC7: 1176 | BD7: 1176 | BF7: 2 | BG7: 505.5 | BI7: 12 | BJ7: 518.46 | BL7: 22 | BM7: 518.46 | BO7: G 01 | CP7: G 01
B8: Piecewise | C8: 0 | E8: G 02 | F8: 0 | G8: 0 | H8: 0 | I8: 0 | J8: 0 | K8: 0 | L8: 0 | M8: 0 | N8: 0 | O8: 0 | P8: 0 | Q8: 0 | R8: 0 | S8: 0 | T8: 0 | U8: 0 | V8: 0 | W8: 0 | X8: 0 | Y8: 0 | Z8: 0 | AA8: 0 | AB8: 0 | AC8: 0 | AE8: G 02 | AF8: PLTGU 1 | AG8: 0 | AH8: 0 | AI8: 0 | AJ8: 0 | AK8: 0 | AL8: 0 | AM8: 0 | AN8: 0 | AO8: 0 | AP8: 0 | AQ8: 0 | AR8: 0 | AS8: 0 | AT8: 0 | AU8: 0 | AV8: 0 | AW8: 0 | AX8: 0 | AY8: 0 | AZ8: 0 | BA8: 0 | BB8: 0 | BC8: 0 | BD8: 0 | BF8: 3 | BG8: 505.5 | BI8: 13 | BJ8: 505.5 | BL8: 23 | BM8: 505.5 | BO8: G 02 | CP8: G 02
A9: Startup Cost | C9: 14016 | E9: G 03 | F9: 1 | G9: 1 | H9: 1 | I9: 1 | J9: 1 | K9: 1 | L9: 1 | M9: 1 | N9: 1 | O9: 1 | P9: 1 | Q9: 1 | R9: 1 | S9: 1 | T9: 1 | U9: 1 | V9: 1 | W9: 1 | X9: 1 | Y9: 1 | Z9: 1 | AA9: 1 | AB9: 1 | AC9: 1 | AE9: G 03 | AF9: PLTU 2 | AG9: 969 | AH9: 969 | AI9: 969 | AJ9: 969 | AK9: 969 | AL9: 969 | AM9: 969 | AN9: 969 | AO9: 969 | AP9: 969 | AQ9: 969 | AR9: 969 | AS9: 969 | AT9: 969 | AU9: 969 | AV9: 969 | AW9: 969 | AX9: 969 | AY9: 969 | AZ9: 969 | BA9: 969 | BB9: 969 | BC9: 969 | BD9: 969 | BF9: 4 | BG9: 505.5 | BI9: 14 | BJ9: 518.46 | BL9: 24 | BM9: 505.5 | BO9: G 03 | CP9: G 03
A10: Shutdown Cost | C10: 0 | E10: G 04 | F10: 0 | G10: 0 | H10: 0 | I10: 0 | J10: 0 | K10: 0 | L10: 0 | M10: 0 | N10: 0 | O10: 0 | P10: 0 | Q10: 0 | R10: 0 | S10: 0 | T10: 1 | U10: 1 | V10: 1 | W10: 0 | X10: 0 | Y10: 1 | Z10: 1 | AA10: 0 | AB10: 0 | AC10: 0 | AE10: G 04 | AF10: PLTG 1 | AG10: 0 | AH10: 0 | AI10: 0 | AJ10: 0 | AK10: 0 | AL10: 0 | AM10: 0 | AN10: 0 | AO10: 0 | AP10: 0 | AQ10: 0 | AR10: 0 | AS10: 0 | AT10: 0 | AU10: 91.427011 | AV10: 112.58914 | AW10: 85 | AX10: 0 | AY10: 0 | AZ10: 116.4 | BA10: 85 | BB10: 0 | BC10: 0 | BD10: 0 | BF10: 5 | BG10: 505.5 | BI10: 15 | BJ10: 534.06 | BO10: G 04 | CP10: G 04
A11: Total Cost | C11: =SUM(C5:C10) -> 3869882.1 | E11: G 05 | F11: 0 | G11: 0 | H11: 0 | I11: 0 | J11: 0 | K11: 0 | L11: 0 | M11: 0 | N11: 0 | O11: 0 | P11: 1 | Q11: 1 | R11: 0 | S11: 1 | T11: 1 | U11: 0 | V11: 0 | W11: 0 | X11: 1 | Y11: 1 | Z11: 1 | AA11: 1 | AB11: 0 | AC11: 0 | AE11: G 05 | AF11: PLTG 2 | AG11: 0 | AH11: 0 | AI11: 0 | AJ11: 0 | AK11: 0 | AL11: 0 | AM11: 0 | AN11: 0 | AO11: 0 | AP11: 0 | AQ11: 66 | AR11: 82.115754 | AS11: 0 | AT11: 66 | AU11: 66 | AV11: 0 | AW11: 0 | AX11: 0 | AY11: 66 | AZ11: 66 | BA11: 66 | BB11: 66 | BC11: 0 | BD11: 0 | BF11: 6 | BG11: 505.5 | BI11: 16 | BJ11: 521.1 | BO11: G 05 | CP11: G 05
E12: G 06 | F12: 1 | G12: 1 | H12: 1 | I12: 1 | J12: 1 | K12: 1 | L12: 1 | M12: 1 | N12: 1 | O12: 1 | P12: 1 | Q12: 1 | R12: 1 | S12: 1 | T12: 1 | U12: 1 | V12: 1 | W12: 1 | X12: 1 | Y12: 1 | Z12: 1 | AA12: 1 | AB12: 1 | AC12: 1 | AE12: G 06 | AF12: PLTGU 2 | AG12: 370.67683 | AH12: 318.16845 | AI12: 250 | AJ12: 250 | AK12: 250 | AL12: 356.52102 | AM12: 418.06041 | AN12: 369.69194 | AO12: 676.45406 | AP12: 992.07191 | AQ12: 1059.9846 | AR12: 1095 | AS12: 926.58459 | AT12: 1034.8113 | AU12: 1095 | AV12: 1095 | AW12: 1060.4488 | AX12: 1045.5568 | AY12: 1031.2723 | AZ12: 1095 | BA12: 1074.6845 | BB12: 1053.2989 | BC12: 848.51896 | BD12: 641.2565 | BF12: 7 | BG12: 505.5 | BI12: 17 | BJ12: 521.1 | BO12: G 06 | CP12: G 06
E13: G 07 | F13: 0 | G13: 0 | H13: 0 | I13: 0 | J13: 0 | K13: 0 | L13: 0 | M13: 0 | N13: 0 | O13: 0 | P13: 0 | Q13: 0 | R13: 0 | S13: 0 | T13: 0 | U13: 0 | V13: 0 | W13: 0 | X13: 0 | Y13: 0 | Z13: 0 | AA13: 0 | AB13: 0 | AC13: 0 | AE13: G 07 | AF13: PLTGU 3 | AG13: 0 | AH13: 0 | AI13: 0 | AJ13: 0 | AK13: 0 | AL13: 0 | AM13: 0 | AN13: 0 | AO13: 0 | AP13: 0 | AQ13: 0 | AR13: 0 | AS13: 0 | AT13: 0 | AU13: 0 | AV13: 0 | AW13: 0 | AX13: 0 | AY13: 0 | AZ13: 0 | BA13: 0 | BB13: 0 | BC13: 0 | BD13: 0 | BF13: 8 | BG13: 505.5 | BI13: 18 | BJ13: 505.5 | BO13: G 07 | CP13: G 07
E14: G 08 | F14: 0 | G14: 0 | H14: 0 | I14: 0 | J14: 0 | K14: 0 | L14: 0 | M14: 0 | N14: 0 | O14: 0 | P14: 0 | Q14: 0 | R14: 0 | S14: 0 | T14: 0 | U14: 0 | V14: 0 | W14: 0 | X14: 0 | Y14: 0 | Z14: 0 | AA14: 0 | AB14: 0 | AC14: 0 | AE14: G 08 | AF14: PLTGU 4 | AG14: 0 | AH14: 0 | AI14: 0 | AJ14: 0 | AK14: 0 | AL14: 0 | AM14: 0 | AN14: 0 | AO14: 0 | AP14: 0 | AQ14: 0 | AR14: 0 | AS14: 0 | AT14: 0 | AU14: 0 | AV14: 0 | AW14: 0 | AX14: 0 | AY14: 0 | AZ14: 0 | BA14: 0 | BB14: 0 | BC14: 0 | BD14: 0 | BF14: 9 | BG14: 505.5 | BI14: 19 | BJ14: 518.46 | BO14: G 08 | CP14: G 08
E15: G 09 | F15: 1 | G15: 1 | H15: 1 | I15: 1 | J15: 1 | K15: 1 | L15: 1 | M15: 1 | N15: 1 | O15: 1 | P15: 1 | Q15: 1 | R15: 1 | S15: 1 | T15: 1 | U15: 1 | V15: 1 | W15: 1 | X15: 1 | Y15: 1 | Z15: 1 | AA15: 1 | AB15: 1 | AC15: 1 | AE15: G 09 | AF15: PLTU 3 | AG15: 870 | AH15: 870 | AI15: 854.20179 | AJ15: 774.38337 | AK15: 870 | AL15: 870 | AM15: 870 | AN15: 870 | AO15: 870 | AP15: 870 | AQ15: 870 | AR15: 870 | AS15: 870 | AT15: 870 | AU15: 870 | AV15: 870 | AW15: 870 | AX15: 870 | AY15: 870 | AZ15: 870 | BA15: 870 | BB15: 870 | BC15: 870 | BD15: 870 | BF15: 10 | BG15: 505.5 | BI15: 20 | BJ15: 534.06 | BO15: G 09 | CP15: G 09
E16: G 10 | F16: 1 | G16: 1 | H16: 1 | I16: 1 | J16: 1 | K16: 1 | L16: 1 | M16: 1 | N16: 1 | O16: 1 | P16: 1 | Q16: 1 | R16: 1 | S16: 1 | T16: 1 | U16: 1 | V16: 1 | W16: 1 | X16: 1 | Y16: 1 | Z16: 1 | AA16: 1 | AB16: 1 | AC16: 1 | AE16: G 10 | AF16: PLTU 4 | AG16: 840 | AH16: 840 | AI16: 840 | AJ16: 840 | AK16: 840 | AL16: 840 | AM16: 840 | AN16: 840 | AO16: 840 | AP16: 840 | AQ16: 840 | AR16: 840 | AS16: 840 | AT16: 840 | AU16: 840 | AV16: 840 | AW16: 840 | AX16: 840 | AY16: 840 | AZ16: 840 | BA16: 840 | BB16: 840 | BC16: 840 | BD16: 840 | BO16: G 10 | CP16: G 10
A19: #2
A20: consInit + consUC + consMUTMDT
A22: Objective | E22: UC Status | AE22: Dispatch | BF22: System Inertia | BO22: Spinning Reserve | CP22: Primary Reserve
A23: Fuel Cost | B23: Quadratic | C23: 0 | E23: Gen | F23: Hour | AE23: Gen | AG23: Hour | BF23: Hour | BG23: Hsys | BI23: Hour | BJ23: Hsys | BL23: Hour | BM23: Hsys | BO23: Gen | BQ23: Hour | CP23: Gen | CR23: Hour
B24: Linear | C24: 3454898.3 | F24: 1 | G24: 2 | H24: 3 | I24: 4 | J24: 5 | K24: 6 | L24: 7 | M24: 8 | N24: 9 | O24: 10 | P24: 11 | Q24: 12 | R24: 13 | S24: 14 | T24: 15 | U24: 16 | V24: 17 | W24: 18 | X24: 19 | Y24: 20 | Z24: 21 | AA24: 22 | AB24: 23 | AC24: 24 | AG24: 1 | AH24: 2 | AI24: 3 | AJ24: 4 | AK24: 5 | AL24: 6 | AM24: 7 | AN24: 8 | AO24: 9 | AP24: 10 | AQ24: 11 | AR24: 12 | AS24: 13 | AT24: 14 | AU24: 15 | AV24: 16 | AW24: 17 | AX24: 18 | AY24: 19 | AZ24: 20 | BA24: 21 | BB24: 22 | BC24: 23 | BD24: 24 | BF24: 1 | BG24: 505.5 | BI24: 11 | BJ24: 521.1 | BL24: 21 | BM24: 534.06 | BQ24: 1 | BR24: 2 | BS24: 3 | BT24: 4 | BU24: 5 | BV24: 6 | BW24: 7 | BX24: 8 | BY24: 9 | BZ24: 10 | CA24: 11 | CB24: 12 | CC24: 13 | CD24: 14 | CE24: 15 | CF24: 16 | CG24: 17 | CH24: 18 | CI24: 19 | CJ24: 20 | CK24: 21 | CL24: 22 | CM24: 23 | CN24: 24 | CR24: 1 | CS24: 2 | CT24: 3 | CU24: 4 | CV24: 5 | CW24: 6 | CX24: 7 | CY24: 8 | CZ24: 9 | DA24: 10 | DB24: 11 | DC24: 12 | DD24: 13 | DE24: 14 | DF24: 15 | DG24: 16 | DH24: 17 | DI24: 18 | DJ24: 19 | DK24: 20 | DL24: 21 | DM24: 22 | DN24: 23 | DO24: 24
B25: No Load | C25: 418325.47 | E25: G 01 | F25: 1 | G25: 1 | H25: 1 | I25: 1 | J25: 1 | K25: 1 | L25: 1 | M25: 1 | N25: 1 | O25: 1 | P25: 1 | Q25: 1 | R25: 1 | S25: 1 | T25: 1 | U25: 1 | V25: 1 | W25: 1 | X25: 1 | Y25: 1 | Z25: 1 | AA25: 1 | AB25: 1 | AC25: 1 | AE25: G 01 | AF25: PLTU 1 | AG25: 1176 | AH25: 1176 | AI25: 1160.2018 | AJ25: 1080.3834 | AK25: 1080.3834 | AL25: 1176 | AM25: 1176 | AN25: 1176 | AO25: 1176 | AP25: 1176 | AQ25: 1176 | AR25: 1176 | AS25: 1176 | AT25: 1176 | AU25: 1176 | AV25: 1176 | AW25: 1176 | AX25: 1176 | AY25: 1176 | AZ25: 1176 | BA25: 1176 | BB25: 1176 | BC25: 1176 | BD25: 1176 | BF25: 2 | BG25: 505.5 | BI25: 12 | BJ25: 521.1 | BL25: 22 | BM25: 521.1 | BO25: G 01 | CP25: G 01
B26: Piecewise | C26: 0 | E26: G 02 | F26: 0 | G26: 0 | H26: 0 | I26: 0 | J26: 0 | K26: 0 | L26: 0 | M26: 0 | N26: 0 | O26: 0 | P26: 0 | Q26: 0 | R26: 0 | S26: 0 | T26: 0 | U26: 0 | V26: 0 | W26: 0 | X26: 0 | Y26: 0 | Z26: 0 | AA26: 0 | AB26: 0 | AC26: 0 | AE26: G 02 | AF26: PLTGU 1 | AG26: 0 | AH26: 0 | AI26: 0 | AJ26: 0 | AK26: 0 | AL26: 0 | AM26: 0 | AN26: 0 | AO26: 0 | AP26: 0 | AQ26: 0 | AR26: 0 | AS26: 0 | AT26: 0 | AU26: 0 | AV26: 0 | AW26: 0 | AX26: 0 | AY26: 0 | AZ26: 0 | BA26: 0 | BB26: 0 | BC26: 0 | BD26: 0 | BF26: 3 | BG26: 505.5 | BI26: 13 | BJ26: 521.1 | BL26: 23 | BM26: 505.5 | BO26: G 02 | CP26: G 02
A27: Startup Cost | C27: 8304 | E27: G 03 | F27: 1 | G27: 1 | H27: 1 | I27: 1 | J27: 1 | K27: 1 | L27: 1 | M27: 1 | N27: 1 | O27: 1 | P27: 1 | Q27: 1 | R27: 1 | S27: 1 | T27: 1 | U27: 1 | V27: 1 | W27: 1 | X27: 1 | Y27: 1 | Z27: 1 | AA27: 1 | AB27: 1 | AC27: 1 | AE27: G 03 | AF27: PLTU 2 | AG27: 969 | AH27: 969 | AI27: 969 | AJ27: 969 | AK27: 969 | AL27: 969 | AM27: 969 | AN27: 969 | AO27: 969 | AP27: 969 | AQ27: 969 | AR27: 969 | AS27: 969 | AT27: 969 | AU27: 969 | AV27: 969 | AW27: 969 | AX27: 969 | AY27: 969 | AZ27: 969 | BA27: 969 | BB27: 969 | BC27: 969 | BD27: 969 | BF27: 4 | BG27: 505.5 | BI27: 14 | BJ27: 521.1 | BL27: 24 | BM27: 505.5 | BO27: G 03 | CP27: G 03
A28: Shutdown Cost | C28: 0 | E28: G 04 | F28: 0 | G28: 0 | H28: 0 | I28: 0 | J28: 0 | K28: 0 | L28: 0 | M28: 0 | N28: 0 | O28: 0 | P28: 1 | Q28: 1 | R28: 1 | S28: 1 | T28: 1 | U28: 1 | V28: 1 | W28: 1 | X28: 1 | Y28: 1 | Z28: 1 | AA28: 1 | AB28: 0 | AC28: 0 | AE28: G 04 | AF28: PLTG 1 | AG28: 0 | AH28: 0 | AI28: 0 | AJ28: 0 | AK28: 0 | AL28: 0 | AM28: 0 | AN28: 0 | AO28: 0 | AP28: 0 | AQ28: 85 | AR28: 85 | AS28: 85 | AT28: 85 | AU28: 91.427011 | AV28: 85 | AW28: 85 | AX28: 85 | AY28: 85 | AZ28: 85 | BA28: 85 | BB28: 85 | BC28: 0 | BD28: 0 | BF28: 5 | BG28: 505.5 | BI28: 15 | BJ28: 534.06 | BO28: G 04 | CP28: G 04
A29: Total Cost | C29: =SUM(C23:C28) -> 3881527.8 | E29: G 05 | F29: 0 | G29: 0 | H29: 0 | I29: 0 | J29: 0 | K29: 0 | L29: 0 | M29: 0 | N29: 0 | O29: 0 | P29: 0 | Q29: 0 | R29: 0 | S29: 0 | T29: 1 | U29: 1 | V29: 0 | W29: 0 | X29: 0 | Y29: 1 | Z29: 1 | AA29: 0 | AB29: 0 | AC29: 0 | AE29: G 05 | AF29: PLTG 2 | AG29: 0 | AH29: 0 | AI29: 0 | AJ29: 0 | AK29: 0 | AL29: 0 | AM29: 0 | AN29: 0 | AO29: 0 | AP29: 0 | AQ29: 0 | AR29: 0 | AS29: 0 | AT29: 0 | AU29: 66 | AV29: 66 | AW29: 0 | AX29: 0 | AY29: 0 | AZ29: 97.4 | BA29: 66 | BB29: 0 | BC29: 0 | BD29: 0 | BF29: 6 | BG29: 505.5 | BI29: 16 | BJ29: 534.06 | BO29: G 05 | CP29: G 05
E30: G 06 | F30: 1 | G30: 1 | H30: 1 | I30: 1 | J30: 1 | K30: 1 | L30: 1 | M30: 1 | N30: 1 | O30: 1 | P30: 1 | Q30: 1 | R30: 1 | S30: 1 | T30: 1 | U30: 1 | V30: 1 | W30: 1 | X30: 1 | Y30: 1 | Z30: 1 | AA30: 1 | AB30: 1 | AC30: 1 | AE30: G 06 | AF30: PLTGU 2 | AG30: 370.67683 | AH30: 318.16845 | AI30: 250 | AJ30: 250 | AK30: 250 | AL30: 356.52102 | AM30: 418.06041 | AN30: 369.69194 | AO30: 676.45406 | AP30: 992.07191 | AQ30: 1040.9846 | AR30: 1092.1158 | AS30: 841.58459 | AT30: 1015.8113 | AU30: 1095 | AV30: 1056.5891 | AW30: 1060.4488 | AX30: 960.55684 | AY30: 1012.2723 | AZ30: 1095 | BA30: 1074.6845 | BB30: 1034.2989 | BC30: 848.51896 | BD30: 641.2565 | BF30: 7 | BG30: 505.5 | BI30: 17 | BJ30: 521.1 | BO30: G 06 | CP30: G 06
E31: G 07 | F31: 0 | G31: 0 | H31: 0 | I31: 0 | J31: 0 | K31: 0 | L31: 0 | M31: 0 | N31: 0 | O31: 0 | P31: 0 | Q31: 0 | R31: 0 | S31: 0 | T31: 0 | U31: 0 | V31: 0 | W31: 0 | X31: 0 | Y31: 0 | Z31: 0 | AA31: 0 | AB31: 0 | AC31: 0 | AE31: G 07 | AF31: PLTGU 3 | AG31: 0 | AH31: 0 | AI31: 0 | AJ31: 0 | AK31: 0 | AL31: 0 | AM31: 0 | AN31: 0 | AO31: 0 | AP31: 0 | AQ31: 0 | AR31: 0 | AS31: 0 | AT31: 0 | AU31: 0 | AV31: 0 | AW31: 0 | AX31: 0 | AY31: 0 | AZ31: 0 | BA31: 0 | BB31: 0 | BC31: 0 | BD31: 0 | BF31: 8 | BG31: 505.5 | BI31: 18 | BJ31: 521.1 | BO31: G 07 | CP31: G 07
E32: G 08 | F32: 0 | G32: 0 | H32: 0 | I32: 0 | J32: 0 | K32: 0 | L32: 0 | M32: 0 | N32: 0 | O32: 0 | P32: 0 | Q32: 0 | R32: 0 | S32: 0 | T32: 0 | U32: 0 | V32: 0 | W32: 0 | X32: 0 | Y32: 0 | Z32: 0 | AA32: 0 | AB32: 0 | AC32: 0 | AE32: G 08 | AF32: PLTGU 4 | AG32: 0 | AH32: 0 | AI32: 0 | AJ32: 0 | AK32: 0 | AL32: 0 | AM32: 0 | AN32: 0 | AO32: 0 | AP32: 0 | AQ32: 0 | AR32: 0 | AS32: 0 | AT32: 0 | AU32: 0 | AV32: 0 | AW32: 0 | AX32: 0 | AY32: 0 | AZ32: 0 | BA32: 0 | BB32: 0 | BC32: 0 | BD32: 0 | BF32: 9 | BG32: 505.5 | BI32: 19 | BJ32: 521.1 | BO32: G 08 | CP32: G 08
E33: G 09 | F33: 1 | G33: 1 | H33: 1 | I33: 1 | J33: 1 | K33: 1 | L33: 1 | M33: 1 | N33: 1 | O33: 1 | P33: 1 | Q33: 1 | R33: 1 | S33: 1 | T33: 1 | U33: 1 | V33: 1 | W33: 1 | X33: 1 | Y33: 1 | Z33: 1 | AA33: 1 | AB33: 1 | AC33: 1 | AE33: G 09 | AF33: PLTU 3 | AG33: 870 | AH33: 870 | AI33: 870 | AJ33: 870 | AK33: 870 | AL33: 870 | AM33: 870 | AN33: 870 | AO33: 870 | AP33: 870 | AQ33: 870 | AR33: 870 | AS33: 870 | AT33: 870 | AU33: 870 | AV33: 870 | AW33: 870 | AX33: 870 | AY33: 870 | AZ33: 870 | BA33: 870 | BB33: 870 | BC33: 870 | BD33: 870 | BF33: 10 | BG33: 505.5 | BI33: 20 | BJ33: 534.06 | BO33: G 09 | CP33: G 09
E34: G 10 | F34: 1 | G34: 1 | H34: 1 | I34: 1 | J34: 1 | K34: 1 | L34: 1 | M34: 1 | N34: 1 | O34: 1 | P34: 1 | Q34: 1 | R34: 1 | S34: 1 | T34: 1 | U34: 1 | V34: 1 | W34: 1 | X34: 1 | Y34: 1 | Z34: 1 | AA34: 1 | AB34: 1 | AC34: 1 | AE34: G 10 | AF34: PLTU 4 | AG34: 840 | AH34: 840 | AI34: 840 | AJ34: 840 | AK34: 840 | AL34: 840 | AM34: 840 | AN34: 840 | AO34: 840 | AP34: 840 | AQ34: 840 | AR34: 840 | AS34: 840 | AT34: 840 | AU34: 840 | AV34: 840 | AW34: 840 | AX34: 840 | AY34: 840 | AZ34: 840 | BA34: 840 | BB34: 840 | BC34: 840 | BD34: 840 | BO34: G 10 | CP34: G 10
A37: #3
A38: consInit + consUC + consMUTMDT + consBasicRamp
A40: Objective | E40: UC Status | AE40: Dispatch | BF40: System Inertia | BO40: Spinning Reserve | CP40: Primary Reserve
A41: Fuel Cost | B41: Quadratic | C41: 0 | E41: Gen | F41: Hour | AE41: Gen | AG41: Hour | BF41: Hour | BG41: Hsys | BI41: Hour | BJ41: Hsys | BL41: Hour | BM41: Hsys | BO41: Gen | BQ41: Hour | CP41: Gen | CR41: Hour
B42: Linear | C42: 3452429.4 | F42: 1 | G42: 2 | H42: 3 | I42: 4 | J42: 5 | K42: 6 | L42: 7 | M42: 8 | N42: 9 | O42: 10 | P42: 11 | Q42: 12 | R42: 13 | S42: 14 | T42: 15 | U42: 16 | V42: 17 | W42: 18 | X42: 19 | Y42: 20 | Z42: 21 | AA42: 22 | AB42: 23 | AC42: 24 | AG42: 1 | AH42: 2 | AI42: 3 | AJ42: 4 | AK42: 5 | AL42: 6 | AM42: 7 | AN42: 8 | AO42: 9 | AP42: 10 | AQ42: 11 | AR42: 12 | AS42: 13 | AT42: 14 | AU42: 15 | AV42: 16 | AW42: 17 | AX42: 18 | AY42: 19 | AZ42: 20 | BA42: 21 | BB42: 22 | BC42: 23 | BD42: 24 | BF42: 1 | BG42: 651.3 | BI42: 11 | BJ42: 651.3 | BL42: 21 | BM42: 651.3 | BQ42: 1 | BR42: 2 | BS42: 3 | BT42: 4 | BU42: 5 | BV42: 6 | BW42: 7 | BX42: 8 | BY42: 9 | BZ42: 10 | CA42: 11 | CB42: 12 | CC42: 13 | CD42: 14 | CE42: 15 | CF42: 16 | CG42: 17 | CH42: 18 | CI42: 19 | CJ42: 20 | CK42: 21 | CL42: 22 | CM42: 23 | CN42: 24 | CR42: 1 | CS42: 2 | CT42: 3 | CU42: 4 | CV42: 5 | CW42: 6 | CX42: 7 | CY42: 8 | CZ42: 9 | DA42: 10 | DB42: 11 | DC42: 12 | DD42: 13 | DE42: 14 | DF42: 15 | DG42: 16 | DH42: 17 | DI42: 18 | DJ42: 19 | DK42: 20 | DL42: 21 | DM42: 22 | DN42: 23 | DO42: 24
B43: No Load | C43: 454586.54 | E43: G 01 | F43: 1 | G43: 1 | H43: 1 | I43: 1 | J43: 1 | K43: 1 | L43: 1 | M43: 1 | N43: 1 | O43: 1 | P43: 1 | Q43: 1 | R43: 1 | S43: 1 | T43: 1 | U43: 1 | V43: 1 | W43: 1 | X43: 1 | Y43: 1 | Z43: 1 | AA43: 1 | AB43: 1 | AC43: 1 | AE43: G 01 | AF43: PLTU 1 | AG43: 1176 | AH43: 1176 | AI43: 1176 | AJ43: 1176 | AK43: 1176 | AL43: 1056 | AM43: 1096.0604 | AN43: 1056 | AO43: 1176 | AP43: 1176 | AQ43: 1176 | AR43: 1176 | AS43: 1176 | AT43: 1176 | AU43: 1176 | AV43: 1176 | AW43: 1176 | AX43: 1176 | AY43: 1176 | AZ43: 1176 | BA43: 1176 | BB43: 1176 | BC43: 1176 | BD43: 1176 | BF43: 2 | BG43: 651.3 | BI43: 12 | BJ43: 651.3 | BL43: 22 | BM43: 651.3 | BO43: G 01 | CP43: G 01
B44: Piecewise | C44: 0 | E44: G 02 | F44: 0 | G44: 0 | H44: 0 | I44: 0 | J44: 0 | K44: 0 | L44: 0 | M44: 0 | N44: 0 | O44: 0 | P44: 0 | Q44: 0 | R44: 0 | S44: 0 | T44: 0 | U44: 0 | V44: 0 | W44: 0 | X44: 0 | Y44: 0 | Z44: 0 | AA44: 0 | AB44: 0 | AC44: 0 | AE44: G 02 | AF44: PLTGU 1 | AG44: 0 | AH44: 0 | AI44: 0 | AJ44: 0 | AK44: 0 | AL44: 0 | AM44: 0 | AN44: 0 | AO44: 0 | AP44: 0 | AQ44: 0 | AR44: 0 | AS44: 0 | AT44: 0 | AU44: 0 | AV44: 0 | AW44: 0 | AX44: 0 | AY44: 0 | AZ44: 0 | BA44: 0 | BB44: 0 | BC44: 0 | BD44: 0 | BF44: 3 | BG44: 651.3 | BI44: 13 | BJ44: 651.3 | BL44: 23 | BM44: 505.5 | BO44: G 02 | CP44: G 02
A45: Startup Cost | C45: 0 | E45: G 03 | F45: 1 | G45: 1 | H45: 1 | I45: 1 | J45: 1 | K45: 1 | L45: 1 | M45: 1 | N45: 1 | O45: 1 | P45: 1 | Q45: 1 | R45: 1 | S45: 1 | T45: 1 | U45: 1 | V45: 1 | W45: 1 | X45: 1 | Y45: 1 | Z45: 1 | AA45: 1 | AB45: 1 | AC45: 1 | AE45: G 03 | AF45: PLTU 2 | AG45: 720 | AH45: 840 | AI45: 960 | AJ45: 880.18159 | AK45: 865.38337 | AL45: 947.52102 | AM45: 969 | AN45: 960.69194 | AO45: 969 | AP45: 969 | AQ45: 969 | AR45: 969 | AS45: 969 | AT45: 969 | AU45: 969 | AV45: 969 | AW45: 969 | AX45: 969 | AY45: 969 | AZ45: 969 | BA45: 969 | BB45: 969 | BC45: 969 | BD45: 969 | BF45: 4 | BG45: 651.3 | BI45: 14 | BJ45: 651.3 | BL45: 24 | BM45: 505.5 | BO45: G 03 | CP45: G 03
A46: Shutdown Cost | C46: 0 | E46: G 04 | F46: 0 | G46: 0 | H46: 0 | I46: 0 | J46: 0 | K46: 0 | L46: 0 | M46: 0 | N46: 0 | O46: 0 | P46: 0 | Q46: 0 | R46: 0 | S46: 0 | T46: 0 | U46: 0 | V46: 0 | W46: 0 | X46: 0 | Y46: 0 | Z46: 0 | AA46: 0 | AB46: 0 | AC46: 0 | AE46: G 04 | AF46: PLTG 1 | AG46: 0 | AH46: 0 | AI46: 0 | AJ46: 0 | AK46: 0 | AL46: 0 | AM46: 0 | AN46: 0 | AO46: 0 | AP46: 0 | AQ46: 0 | AR46: 0 | AS46: 0 | AT46: 0 | AU46: 0 | AV46: 0 | AW46: 0 | AX46: 0 | AY46: 0 | AZ46: 0 | BA46: 0 | BB46: 0 | BC46: 0 | BD46: 0 | BF46: 5 | BG46: 651.3 | BI46: 15 | BJ46: 651.3 | BO46: G 04 | CP46: G 04
A47: Total Cost | C47: =SUM(C41:C46) -> 3907015.9 | E47: G 05 | F47: 0 | G47: 0 | H47: 0 | I47: 0 | J47: 0 | K47: 0 | L47: 0 | M47: 0 | N47: 0 | O47: 0 | P47: 0 | Q47: 0 | R47: 0 | S47: 0 | T47: 0 | U47: 0 | V47: 0 | W47: 0 | X47: 0 | Y47: 0 | Z47: 0 | AA47: 0 | AB47: 0 | AC47: 0 | AE47: G 05 | AF47: PLTG 2 | AG47: 0 | AH47: 0 | AI47: 0 | AJ47: 0 | AK47: 0 | AL47: 0 | AM47: 0 | AN47: 0 | AO47: 0 | AP47: 0 | AQ47: 0 | AR47: 0 | AS47: 0 | AT47: 0 | AU47: 0 | AV47: 0 | AW47: 0 | AX47: 0 | AY47: 0 | AZ47: 0 | BA47: 0 | BB47: 0 | BC47: 0 | BD47: 0 | BF47: 6 | BG47: 651.3 | BI47: 16 | BJ47: 651.3 | BO47: G 05 | CP47: G 05
...

Sheet Dispatch
A1: Hour | B1: 1 | C1: 2 | D1: 3 | E1: 4 | F1: 5 | G1: 6 | H1: 7 | I1: 8 | J1: 9 | K1: 10 | L1: 11 | M1: 12 | N1: 13 | O1: 14 | P1: 15 | Q1: 16 | R1: 17 | S1: 18 | T1: 19 | U1: 20 | V1: 21 | W1: 22 | X1: 23 | Y1: 24
A2: Demand | B2: 4225.68 | C2: 4173.17 | D2: 4089.2 | E2: 4009.38 | F2: 4009.38 | G2: 4211.52 | H2: 4273.06 | I2: 4224.69 | J2: 4531.45 | K2: 4847.07 | L2: 4980.98 | M2: 5032.12 | N2: 4781.58 | O2: 4955.81 | P2: 5107.43 | Q2: 5062.59 | R2: 5000.45 | S2: 4900.56 | T2: 4952.27 | U2: 5132.4 | V2: 5080.68 | W2: 4974.3 | X2: 4703.52 | Y2: 4496.26
A3: G1_P | B3: 1056 | C3: 940.8 | D3: 820.8 | E3: 700.8 | F3: 627 | G3: 745.98 | H3: 745.98 | I3: 745.98 | J3: 673.98 | K3: 633.59 | L3: 673.98 | M3: 673.98 | N3: 745.98 | O3: 772.8 | P3: 820.8 | Q3: 940.8 | R3: 940.8 | S3: 909.83 | T3: 789.83 | U3: 759.59 | V3: 656.22 | W3: 745.98 | X3: 633.59 | Y3: 705.86
A4: G2_P | B4: 340 | C4: 340 | D4: 340 | E4: 340 | F4: 340 | G4: 340 | H4: 340 | I4: 340 | J4: 340 | K4: 340 | L4: 487.02 | M4: 340 | N4: 509.26 | O4: 588 | P4: 535.11 | Q4: 384.04 | R4: 600 | S4: 900 | T4: 600 | U4: 588.78 | V4: 360.46 | W4: 463.51 | X4: 340 | Y4: 0
A5: G3_P | B5: 720 | C5: 769.62 | D5: 829.68 | E5: 921.01 | F5: 969 | G5: 969 | H5: 969 | I5: 969 | J5: 969 | K5: 969 | L5: 969 | M5: 969 | N5: 969 | O5: 942.18 | P5: 822.18 | Q5: 747.93 | R5: 747.93 | S5: 775.2 | T5: 763.4 | U5: 883.4 | V5: 969 | W5: 969 | X5: 871.64 | Y5: 789.72
A6: G4_P | B6: 85 | C6: 0 | D6: 0 | E6: 0 | F6: 0 | G6: 0 | H6: 0 | I6: 0 | J6: 0 | K6: 0 | L6: 0 | M6: 0 | N6: 0 | O6: 0 | P6: 0 | Q6: 0 | R6: 0 | S6: 0 | T6: 0 | U6: 0 | V6: 0 | W6: 0 | X6: 0 | Y6: 0
A7: G5_P | B7: 66 | C7: 0 | D7: 0 | E7: 0 | F7: 0 | G7: 0 | H7: 0 | I7: 0 | J7: 0 | K7: 0 | L7: 0 | M7: 0 | N7: 0 | O7: 0 | P7: 0 | Q7: 0 | R7: 0 | S7: 0 | T7: 0 | U7: 0 | V7: 0 | W7: 0 | X7: 0 | Y7: 0
A8: G6_P | B8: 250 | C8: 250 | D8: 250 | E8: 250 | F8: 250 | G8: 250 | H8: 366.52 | I8: 250 | J8: 550 | K8: 850 | L8: 922.41 | M8: 876 | N8: 576 | O8: 876 | P8: 876 | Q8: 1008.01 | R8: 882.01 | S8: 582.01 | T8: 882.01 | U8: 1008.01 | V8: 876 | W8: 964.2 | X8: 876 | Y8: 882.25
A9: G7_P | B9: 248 | C9: 248 | D9: 248 | E9: 248 | F9: 248 | G9: 407.92 | H9: 256.14 | I9: 556.14 | J9: 431.64 | K9: 344.86 | L9: 348 | M9: 648 | N9: 736.56 | O9: 436.56 | P9: 648 | Q9: 648 | R9: 391.82 | S9: 280.09 | T9: 315.33 | U9: 348 | V9: 648 | W9: 348 | X9: 348 | Y9: 648
A10: G8_P | B10: 0 | C10: 0 | D10: 0 | E10: 0 | F10: 0 | G10: 0 | H10: 0 | I10: 0 | J10: 0 | K10: 0 | L10: 0 | M10: 0 | N10: 0 | O10: 0 | P10: 0 | Q10: 0 | R10: 0 | S10: 0 | T10: 0 | U10: 0 | V10: 0 | W10: 0 | X10: 0 | Y10: 0
A11: G9_P | B11: 540.68 | C11: 606.24 | D11: 657.78 | E11: 696 | F11: 683.63 | G11: 606.24 | H11: 606.24 | I11: 606.24 | J11: 606.24 | K11: 646.64 | L11: 606.24 | M11: 606.24 | N11: 606.24 | O11: 606.24 | P11: 606.24 | Q11: 632.49 | R11: 632.49 | S11: 636.2 | T11: 696 | U11: 606.24 | V11: 696 | W11: 606.24 | X11: 696 | Y11: 676.55
A12: G10_P | B12: 600 | C12: 600 | D12: 600 | E12: 600 | F12: 600 | G12: 600 | H12: 600 | I12: 600 | J12: 672 | K12: 672 | L12: 672 | M12: 672 | N12: 600 | O12: 600 | P12: 672 | Q12: 600 | R12: 600 | S12: 600 | T12: 672 | U12: 672 | V12: 600 | W12: 600 | X12: 720 | Y12: 607.41
... A16: Total_Power | B16: 4305.68 | C16: 4093.17 | D16: 4093.7 | E16: 4089.38 | F16: 4089.38 | G16: 4191.52 | H16: 4193.06 | I16: 4304.69 | J16: 4551.45 | K16: 4847.07 | L16: 4967.31 | M16: 4965.79 | N16: 4861.58 | O16: 4955.81 | P16: 5107.43 | Q16: 5062.59 | R16: 4980.45 | S16: 4900.56 | T16: 4952.27 | U16: 5132.4 | V16: 5061.18 | W16: 4894.3 | X16: 4704.69 | Y16: 4450.09

Sheet Battery
A1: Hour | B1: 1 | C1: 2 | D1: 3 | E1: 4 | F1: 5 | G1: 6 | H1: 7 | I1: 8 | J1: 9 | K1: 10 | L1: 11 | M1: 12 | N1: 13 | O1: 14 | P1: 15 | Q1: 16 | R1: 17 | S1: 18 | T1: 19 | U1: 20 | V1: 21 | W1: 22 | X1: 23 | Y1: 24
A2: B1_P_charge | B2: 60 | C2: 0 | D2: 19.5 | E2: 60 | F2: 60 | G2: 0 | H2: 0 | I2: 60 | J2: 0 | K2: 0 | L2: 0 | M2: 0 | N2: 60 | O2: 0 | P2: 0 | Q2: 0 | R2: 0 | S2: 0 | T2: 0 | U2: 0 | V2: 0 | W2: 0 | X2: 0 | Y2: 0
A3: B1_P_discharge | B3: 0 | C3: 60 | D3: 0 | E3: 0 | F3: 0 | G3: 0 | H3: 60 | I3: 0 | J3: 0 | K3: 0 | L3: 0 | M3: 60 | N3: 0 | O3: 0 | P3: 0 | Q3: 0 | R3: 0 | S3: 0 | T3: 0 | U3: 0 | V3: 19.5 | W3: 60 | X3: 0 | Y3: 60
A4: B1_SOC | B4: 75.5 | C4: 15.5 | D4: 35 | E4: 95 | F4: 155 | G4: 155 | H4: 95 | I4: 155 | J4: 155 | K4: 155 | L4: 155 | M4: 95 | N4: 155 | O4: 155 | P4: 155 | Q4: 155 | R4: 155 | S4: 155 | T4: 155 | U4: 155 | V4: 135.5 | W4: 75.5 | X4: 75.5 | Y4: 15.5
A5: B1_ChargeStatus | B5: 1 | C5: 0 | D5: 1 | E5: 1 | F5: 1 | G5: 0 | H5: 0 | I5: 1 | J5: 1 | K5: 1 | L5: 0 | M5: 0 | N5: 1 | O5: 0 | P5: 0 | Q5: 0 | R5: 0 | S5: 1 | T5: 0 | U5: 0 | V5: 0 | W5: 0 | X5: 0 | Y5: 0
A6: B1_DischargeStatus | B6: 0 | C6: 1 | D6: 0 | E6: 0 | F6: 0 | G6: 1 | H6: 1 | I6: 0 | J6: 0 | K6: 0 | L6: 1 | M6: 1 | N6: 0 | O6: 1 | P6: 1 | Q6: 1 | R6: 1 | S6: 0 | T6: 1 | U6: 1 | V6: 1 | W6: 1 | X6: 1 | Y6: 1
A7: B2_P_charge | B7: 20 | C7: 0 | D7: 0 | E7: 20 | F7: 20 | G7: 0 | H7: 0 | I7: 20 | J7: 20 | K7: 0 | L7: 0 | M7: 0 | N7: 20 | O7: 0 | P7: 0 | Q7: 0 | R7: 0 | S7: 0 | T7: 0 | U7: 0 | V7: 0 | W7: 0 | X7: 1.1699021 | Y7: 13.830098
A8: B2_P_discharge | B8: 0 | C8: 20 | D8: 15 | E8: 0 | F8: 0 | G8: 20 | H8: 20 | I8: 0 | J8: 0 | K8: 0 | L8: 13.669906 | M8: 6.3300935 | N8: 0 | O8: 0 | P8: 0 | Q8: 0 | R8: 20 | S8: 0 | T8: 0 | U8: 0 | V8: 0 | W8: 20 | X8: 0 | Y8: 0
A9: B2_SOC | B9: 45 | C9: 25 | D9: 10 | E9: 30 | F9: 50 | G9: 30 | H9: 10 | I9: 30 | J9: 50 | K9: 50 | L9: 36.330094 | M9: 30 | N9: 50 | O9: 50 | P9: 50 | Q9: 50 | R9: 30 | S9: 30 | T9: 30 | U9: 30 | V9: 30 | W9: 10 | X9: 11.169902 | Y9: 25
A10: B2_ChargeStatus | B10: 1 | C10: 0 | D10: 0 | E10: 1 | F10: 1 | G10: 0 | H10: 0 | I10: 1 | J10: 1 | K10: 0 | L10: 0 | M10: 0 | N10: 1 | O10: 0 | P10: 0 | Q10: 0 | R10: 0 | S10: 1 | T10: 1 | U10: 0 | V10: 0 | W10: 0 | X10: 1 | Y10: 1
A11: B2_DischargeStatus | B11: 0 | C11: 1 | D11: 1 | E11: 0 | F11: 0 | G11: 1 | H11: 1 | I11: 0 | J11: 0 | K11: 1 | L11: 1 | M11: 1 | N11: 0 | O11: 1 | P11: 1 | Q11: 1 | R11: 1 | S11: 0 | T11: 0 | U11: 1 | V11: 1 | W11: 1 | X11: 0 | Y11: 0
A14: Power | B14: =(B2+B7)-(B3+B8) -> 80 | C14: =(C2+C7)-(C3+C8) -> -80 | D14: =(D2+D7)-(D3+D8) -> 4.5 | E14: =(E2+E7)-(E3+E8) -> 80 | F14: =(F2+F7)-(F3+F8) -> 80 | G14: =(G2+G7)-(G3+G8) -> -20 | H14: =(H2+H7)-(H3+H8) -> -80 | I14: =(I2+I7)-(I3+I8) -> 80 | ... Y14: =(Y2+Y7)-(Y3+Y8) -> -46.169902
A15: SOC | B15: =B4+B9 -> 120.5 | C15: =C4+C9 -> 40.5 | D15: =D4+D9 -> 45 | E15: =E4+E9 -> 125 | F15: =F4+F9 -> 205 | G15: =G4+G9 -> 185 | H15: =H4+H9 -> 105 | I15: =I4+I9 -> 185 | ... Y15: =Y4+Y9 -> 40.5

Sheet Sheet5
A1: #5 | consInit + consUC + consMUTMDT + consBasicRamp + consSRContingency + consWorstCaseInertia
A2: Spinning - Reserve | AB2: Status Contingency (0, jika lepas) | BC2: Reserve
A3: Gen | C3: Hour | AB3: Gen | AD3: Hour | BC3: Spinning Reserve | BD3: Hour
C4: 1 | D4: 2 | E4: 3 | F4: 4 | G4: 5 | H4: 6 | I4: 7 | J4: 8 | K4: 9 | L4: 10 | M4: 11 | N4: 12 | O4: 13 | P4: 14 | Q4: 15 | R4: 16 | S4: 17 | T4: 18 | U4: 19 | V4: 20 | W4: 21 | X4: 22 | Y4: 23 | Z4: 24 | AD4: 1 | AE4: 2 | AF4: 3 | AG4: 4 | AH4: 5 | AI4: 6 | AJ4: 7 | AK4: 8 | AL4: 9 | AM4: 10 | AN4: 11 | AO4: 12 | AP4: 13 | AQ4: 14 | AR4: 15 | AS4: 16 | AT4: 17 | AU4: 18 | AV4: 19 | AW4: 20 | AX4: 21 | AY4: 22 | AZ4: 23 | BA4: 24 | BD4: 1 | BE4: 2 | BF4: 3 | BG4: 4 | BH4: 5 | BI4: 6 | BJ4: 7 | BK4: 8 | BL4: 9 | BM4: 10 | BN4: 11 | BO4: 12 | BP4: 13 | BQ4: 14 | BR4: 15 | BS4: 16 | BT4: 17 | BU4: 18 | BV4: 19 | BW4: 20 | BX4: 21 | BY4: 22 | BZ4: 23 | CA4: 24
A5: G 01 | B5: PLTU 1 | C5: =Sheet1!BQ79-Sheet1!CR79 -> 0 | D5: =Sheet1!BR79-Sheet1!CS79 -> 207 | E5: =Sheet1!BS79-Sheet1!CT79 -> 207 | F5: =Sheet1!BT79-Sheet1!CU79 -> 207 | G5: =Sheet1!BU79-Sheet1!CV79 -> 207 | H5: =Sheet1!BV79-Sheet1!CW79 -> 207 | I5: =Sheet1!BW79-Sheet1!CX79 -> 207 | J5: =Sheet1!BX79-Sheet1!CY79 -> 207 | ... Z5: =Sheet1!CN79-Sheet1!DO79 -> 207 | AB5: G 01 | AC5: PLTU 1 | AD5: =IF(Sheet1!AG79=MAX(Sheet1!AG$79:AG$88),0,1) -> 0 | AE5: =IF(Sheet1!AH79=MAX(Sheet1!AH$79:AH$88),0,1) -> 0 | AF5: =IF(Sheet1!AI79=MAX(Sheet1!AI$79:AI$88),0,1) -> 0 | AG5: =IF(Sheet1!AJ79=MAX(Sheet1!AJ$79:AJ$88),0,1) -> 0 | AH5: =IF(Sheet1!AK79=MAX(Sheet1!AK$79:AK$88),0,1) -> 0 | AI5: =IF(Sheet1!AL79=MAX(Sheet1!AL$79:AL$88),0,1) -> 0 | AJ5: =IF(Sheet1!AM79=MAX(Sheet1!AM$79:AM$88),0,1) -> 1 | AK5: =IF(Sheet1!AN79=MAX(Sheet1!AN$79:AN$88),0,1) -> 1 | ... BA5: =IF(Sheet1!BD79=MAX(Sheet1!BD$79:BD$88),0,1) -> 1 | BC5: Ploss | BD5: =MAX(Sheet1!AG79:AG88) -> 1056 | BE5: =MAX(Sheet1!AH79:AH88) -> 936 | BF5: =MAX(Sheet1!AI79:AI88) -> 816 | BG5: =MAX(Sheet1!AJ79:AJ88) -> 773.74135 | BH5: =MAX(Sheet1!AK79:AK88) -> 893.74135 | BI5: =MAX(Sheet1!AL79:AL88) -> 773.74135 | BJ5: =MAX(Sheet1!AM79:AM88) -> 870 | BK5: =MAX(Sheet1!AN79:AN88) -> 870 | ... CA5: =MAX(Sheet1!BD79:BD88) -> 902.90128
A6: G 02 | B6: PLTGU 1 | C6: =Sheet1!BQ80-Sheet1!CR80 -> 688.22274 | D6: =Sheet1!BR80-Sheet1!CS80 -> 590.44627 | E6: =Sheet1!BS80-Sheet1!CT80 -> 703.20348 | F6: =Sheet1!BT80-Sheet1!CU80 -> 703.20348 | G6: =Sheet1!BU80-Sheet1!CV80 -> 453.04417 | H6: =Sheet1!BV80-Sheet1!CW80 -> 703.20348 | I6: =Sheet1!BW80-Sheet1!CX80 -> 556.42754 | J6: =Sheet1!BX80-Sheet1!CY80 -> 604.79601 | ... Z6: =Sheet1!CN80-Sheet1!DO80 -> 156 | AB6: G 02 | AC6: PLTGU 1 | AD6: =IF(Sheet1!AG80=MAX(Sheet1!AG$79:AG$88),0,1) -> 1 | AE6: =IF(Sheet1!AH80=MAX(Sheet1!AH$79:AH$88),0,1) -> 1 | AF6: =IF(Sheet1!AI80=MAX(Sheet1!AI$79:AI$88),0,1) -> 1 | AG6: =IF(Sheet1!AJ80=MAX(Sheet1!AJ$79:AJ$88),0,1) -> 1 | AH6: =IF(Sheet1!AK80=MAX(Sheet1!AK$79:AK$88),0,1) -> 1 | AI6: =IF(Sheet1!AL80=MAX(Sheet1!AL$79:AL$88),0,1) -> 1 | AJ6: =IF(Sheet1!AM80=MAX(Sheet1!AM$79:AM$88),0,1) -> 1 | AK6: =IF(Sheet1!AN80=MAX(Sheet1!AN$79:AN$88),0,1) -> 1 | ... BA6: =IF(Sheet1!BD80=MAX(Sheet1!BD$79:BD$88),0,1) -> 0 | BC6: Spinning Total | BD6: =SUM(Sheet1!BQ79:BQ88) -> 3432.3232 | BE6: =SUM(Sheet1!BR79:BR88) -> 2711.8315 | BF6: =SUM(Sheet1!BS79:BS88) -> 2795.7982 | BG6: =SUM(Sheet1!BT79:BT88) -> 2875.6166 | BH6: =SUM(Sheet1!BU79:BU88) -> 2875.6166 | BI6: =SUM(Sheet1!BV79:BV88) -> 2673.479 | BJ6: =SUM(Sheet1!BW79:BW88) -> 2611.9396 | BK6: =SUM(Sheet1!BX79:BX88) -> 2660.3081 | ... CA6: =SUM(Sheet1!CN79:CN88) -> 1578.7435
A7: G 03 | B7: PLTU 2 | C7: =Sheet1!BQ81-Sheet1!CR81 -> 0 | D7: =Sheet1!BR81-Sheet1!CS81 -> 0 | E7: =Sheet1!BS81-Sheet1!CT81 -> 0 | F7: =Sheet1!BT81-Sheet1!CU81 -> 0 | G7: =Sheet1!BU81-Sheet1!CV81 -> 0 | H7: =Sheet1!BV81-Sheet1!CW81 -> 0 | I7: =Sheet1!BW81-Sheet1!CX81 -> 0 | J7: =Sheet1!BX81-Sheet1!CY81 -> 0 | ... Z7: =Sheet1!CN81-Sheet1!DO81 -> 0 | AB7: G 03 | AC7: PLTU 2 | AD7: =IF(Sheet1!AG81=MAX(Sheet1!AG$79:AG$88),0,1) -> 1 | AE7: =IF(Sheet1!AH81=MAX(Sheet1!AH$79:AH$88),0,1) -> 1 | AF7: =IF(Sheet1!AI81=MAX(Sheet1!AI$79:AI$88),0,1) -> 1 | AG7: =IF(Sheet1!AJ81=MAX(Sheet1!AJ$79:AJ$88),0,1) -> 1 | AH7: =IF(Sheet1!AK81=MAX(Sheet1!AK$79:AK$88),0,1) -> 1 | AI7: =IF(Sheet1!AL81=MAX(Sheet1!AL$79:AL$88),0,1) -> 0 | AJ7: =IF(Sheet1!AM81=MAX(Sheet1!AM$79:AM$88),0,1) -> 1 | AK7: =IF(Sheet1!AN81=MAX(Sheet1!AN$79:AN$88),0,1) -> 1 | ... BA7: =IF(Sheet1!BD81=MAX(Sheet1!BD$79:BD$88),0,1) -> 1 | BC7: Spinning Back Up | BD7: =SUMPRODUCT(Sheet1!BQ79:BQ88,Sheet5!AD5:AD14) -> 3312.3232 | BE7: =SUMPRODUCT(Sheet1!BR79:BR88,Sheet5!AE5:AE14) -> 2471.8315 | BF7: =SUMPRODUCT(Sheet1!BS79:BS88,Sheet5!AF5:AF14) -> 2435.7982 | BG7: =SUMPRODUCT(Sheet1!BT79:BT88,Sheet5!AG5:AG14) -> 2473.358 | BH7: =SUMPRODUCT(Sheet1!BU79:BU88,Sheet5!AH5:AH14) -> 2593.358 | BI7: =SUMPRODUCT(Sheet1!BV79:BV88,Sheet5!AI5:AI14) -> 1979.703 | BJ7: =SUMPRODUCT(Sheet1!BW79:BW88,Sheet5!AJ5:AJ14) -> 2611.9396 | BK7: =SUMPRODUCT(Sheet1!BX79:BX88,Sheet5!AK5:AK14) -> 2660.3081 | ... CA7: =SUMPRODUCT(Sheet1!CN79:CN88,Sheet5!BA5:BA14) -> 1356.6448
A8: G 04 | B8: PLTG 1 | C8: =Sheet1!BQ82-Sheet1!CR82 -> 0 | D8: =Sheet1!BR82-Sheet1!CS82 -> 0 | E8: =Sheet1!BS82-Sheet1!CT82 -> 0 | F8: =Sheet1!BT82-Sheet1!CU82 -> 0 | G8: =Sheet1!BU82-Sheet1!CV82 -> 0 | H8: =Sheet1!BV82-Sheet1!CW82 -> 0 | I8: =Sheet1!BW82-Sheet1!CX82 -> 0 | J8: =Sheet1!BX82-Sheet1!CY82 -> 0 | ... Z8: =Sheet1!CN82-Sheet1!DO82 -> 0 | AB8: G 04 | AC8: PLTG 1 | AD8: =IF(Sheet1!AG82=MAX(Sheet1!AG$79:AG$88),0,1) -> 1 | AE8: =IF(Sheet1!AH82=MAX(Sheet1!AH$79:AH$88),0,1) -> 1 | AF8: =IF(Sheet1!AI82=MAX(Sheet1!AI$79:AI$88),0,1) -> 1 | AG8: =IF(Sheet1!AJ82=MAX(Sheet1!AJ$79:AJ$88),0,1) -> 1 | AH8: =IF(Sheet1!AK82=MAX(Sheet1!AK$79:AK$88),0,1) -> 1 | AI8: =IF(Sheet1!AL82=MAX(Sheet1!AL$79:AL$88),0,1) -> 1 | AJ8: =IF(Sheet1!AM82=MAX(Sheet1!AM$79:AM$88),0,1) -> 1 | AK8: =IF(Sheet1!AN82=MAX(Sheet1!AN$79:AN$88),0,1) -> 1 | ... BA8: =IF(Sheet1!BD82=MAX(Sheet1!BD$79:BD$88),0,1) -> 1 | BC8: Primary Total | BD8: =SUM(Sheet1!CR79:CR88) -> 1176 | BE8: =SUM(Sheet1!CS79:CS88) -> 969 | BF8: =SUM(Sheet1!CT79:CT88) -> 969 | BG8: =SUM(Sheet1!CU79:CU88) -> 969 | BH8: =SUM(Sheet1!CV79:CV88) -> 969 | BI8: =SUM(Sheet1!CW79:CW88) -> 969 | BJ8: =SUM(Sheet1!CX79:CX88) -> 969 | BK8: =SUM(Sheet1!CY79:CY88) -> 969 | ... CA8: =SUM(Sheet1!DO79:DO88) -> 969
A9: G 05 | B9: PLTG 2 | C9: =Sheet1!BQ83-Sheet1!CR83 -> 0 | D9: =Sheet1!BR83-Sheet1!CS83 -> 0 | E9: =Sheet1!BS83-Sheet1!CT83 -> 0 | F9: =Sheet1!BT83-Sheet1!CU83 -> 0 | G9: =Sheet1!BU83-Sheet1!CV83 -> 0 | H9: =Sheet1!BV83-Sheet1!CW83 -> 0 | I9: =Sheet1!BW83-Sheet1!CX83 -> 0 | J9: =Sheet1!BX83-Sheet1!CY83 -> 0 | ... Z9: =Sheet1!CN83-Sheet1!DO83 -> 0 | AB9: G 05 | AC9: PLTG 2 | AD9: =IF(Sheet1!AG83=MAX(Sheet1!AG$79:AG$88),0,1) -> 1 | AE9: =IF(Sheet1!AH83=MAX(Sheet1!AH$79:AH$88),0,1) -> 1 | AF9: =IF(Sheet1!AI83=MAX(Sheet1!AI$79:AI$88),0,1) -> 1 | AG9: =IF(Sheet1!AJ83=MAX(Sheet1!AJ$79:AJ$88),0,1) -> 1 | AH9: =IF(Sheet1!AK83=MAX(Sheet1!AK$79:AK$88),0,1) -> 1 | AI9: =IF(Sheet1!AL83=MAX(Sheet1!AL$79:AL$88),0,1) -> 1 | AJ9: =IF(Sheet1!AM83=MAX(Sheet1!AM$79:AM$88),0,1) -> 1 | AK9: =IF(Sheet1!AN83=MAX(Sheet1!AN$79:AN$88),0,1) -> 1 | ... BA9: =IF(Sheet1!BD83=MAX(Sheet1!BD$79:BD$88),0,1) -> 1 | BC9: Primary Back Up | BD9: =SUMPRODUCT(Sheet1!CR79:CR88,Sheet5!AD5:AD14) -> 1056 | BE9: =SUMPRODUCT(Sheet1!CS79:CS88,Sheet5!AE5:AE14) -> 936 | BF9: =SUMPRODUCT(Sheet1!CT79:CT88,Sheet5!AF5:AF14) -> 816 | BG9: =SUMPRODUCT(Sheet1!CU79:CU88,Sheet5!AG5:AG14) -> 773.74135 | BH9: =SUMPRODUCT(Sheet1!CV79:CV88,Sheet5!AH5:AH14) -> 893.74135 | BI9: =SUMPRODUCT(Sheet1!CW79:CW88,Sheet5!AI5:AI14) -> 482.22406 | BJ9: =SUMPRODUCT(Sheet1!CX79:CX88,Sheet5!AJ5:AJ14) -> 969 | BK9: =SUMPRODUCT(Sheet1!CY79:CY88,Sheet5!AK5:AK14) -> 969 | ... CA9: =SUMPRODUCT(Sheet1!DO79:DO88,Sheet5!BA5:BA14) -> 902.90128
A10: G 06 | B10: PLTGU 2 | C10: =Sheet1!BQ84-Sheet1!CR84 -> 742.08053 | D10: =Sheet1!BR84-Sheet1!CS84 -> 756.82488 | E10: =Sheet1!BS84-Sheet1!CT84 -> 458.01206 | F10: =Sheet1!BT84-Sheet1!CU84 -> 758.01206 | G10: =Sheet1!BU84-Sheet1!CV84 -> 758.01206 | H10: =Sheet1!BV84-Sheet1!CW84 -> 605.7151 | I10: =Sheet1!BW84-Sheet1!CX84 -> 426 | J10: =Sheet1!BX84-Sheet1!CY84 -> 726 | ... Z10: =Sheet1!CN84-Sheet1!DO84 -> 246.7435 | AB10: G 06 | AC10: PLTGU 2 | AD10: =IF(Sheet1!AG84=MAX(Sheet1!AG$79:AG$88),0,1) -> 1 | AE10: =IF(Sheet1!AH84=MAX(Sheet1!AH$79:AH$88),0,1) -> 1 | AF10: =IF(Sheet1!AI84=MAX(Sheet1!AI$79:AI$88),0,1) -> 1 | AG10: =IF(Sheet1!AJ84=MAX(Sheet1!AJ$79:AJ$88),0,1) -> 1 | AH10: =IF(Sheet1!AK84=MAX(Sheet1!AK$79:AK$88),0,1) -> 1 | AI10: =IF(Sheet1!AL84=MAX(Sheet1!AL$79:AL$88),0,1) -> 1 | AJ10: =IF(Sheet1!AM84=MAX(Sheet1!AM$79:AM$88),0,1) -> 1 | AK10: =IF(Sheet1!AN84=MAX(Sheet1!AN$79:AN$88),0,1) -> 1 | ... BA10: =IF(Sheet1!BD84=MAX(Sheet1!BD$79:BD$88),0,1) -> 1
A11: G 07 | B11: PLTGU 3 | C11: =Sheet1!BQ85-Sheet1!CR85 -> 485.36274 | D11: =Sheet1!BR85-Sheet1!CS85 -> 188.5604 | E11: =Sheet1!BS85-Sheet1!CT85 -> 458.58267 | F11: =Sheet1!BT85-Sheet1!CU85 -> 238.40109 | G11: =Sheet1!BU85-Sheet1!CV85 -> 488.5604 | H11: =Sheet1!BV85-Sheet1!CW85 -> 188.5604 | I11: =Sheet1!BW85-Sheet1!CX85 -> 453.51205 | J11: =Sheet1!BX85-Sheet1!CY85 -> 153.51205 | ... Z11: =Sheet1!CN85-Sheet1!DO85 -> 0 | AB11: G 07 | AC11: PLTGU 3 | AD11: =IF(Sheet1!AG85=MAX(Sheet1!AG$79:AG$88),0,1) -> 1 | AE11: =IF(Sheet1!AH85=MAX(Sheet1!AH$79:AH$88),0,1) -> 1 | AF11: =IF(Sheet1!AI85=MAX(Sheet1!AI$79:AI$88),0,1) -> 1 | AG11: =IF(Sheet1!AJ85=MAX(Sheet1!AJ$79:AJ$88),0,1) -> 1 | AH11: =IF(Sheet1!AK85=MAX(Sheet1!AK$79:AK$88),0,1) -> 1 | AI11: =IF(Sheet1!AL85=MAX(Sheet1!AL$79:AL$88),0,1) -> 1 | AJ11: =IF(Sheet1!AM85=MAX(Sheet1!AM$79:AM$88),0,1) -> 1 | AK11: =IF(Sheet1!AN85=MAX(Sheet1!AN$79:AN$88),0,1) -> 1 | ... BA11: =IF(Sheet1!BD85=MAX(Sheet1!BD$79:BD$88),0,1) -> 1
A12: G 08 | B12: PLTGU 4 | C12: =Sheet1!BQ86-Sheet1!CR86 -> 340.65716 | D12: =Sheet1!BR86-Sheet1!CS86 -> 0 | E12: =Sheet1!BS86-Sheet1!CT86 -> 0 | F12: =Sheet1!BT86-Sheet1!CU86 -> 0 | G12: =Sheet1!BU86-Sheet1!CV86 -> 0 | H12: =Sheet1!BV86-Sheet1!CW86 -> 0 | I12: =Sheet1!BW86-Sheet1!CX86 -> 0 | J12: =Sheet1!BX86-Sheet1!CY86 -> 0 | ... Z12: =Sheet1!CN86-Sheet1!DO86 -> 0 | AB12: G 08 | AC12: PLTGU 4 | AD12: =IF(Sheet1!AG86=MAX(Sheet1!AG$79:AG$88),0,1) -> 1 | AE12: =IF(Sheet1!AH86=MAX(Sheet1!AH$79:AH$88),0,1) -> 1 | AF12: =IF(Sheet1!AI86=MAX(Sheet1!AI$79:AI$88),0,1) -> 1 | AG12: =IF(Sheet1!AJ86=MAX(Sheet1!AJ$79:AJ$88),0,1) -> 1 | AH12: =IF(Sheet1!AK86=MAX(Sheet1!AK$79:AK$88),0,1) -> 1 | AI12: =IF(Sheet1!AL86=MAX(Sheet1!AL$79:AL$88),0,1) -> 1 | AJ12: =IF(Sheet1!AM86=MAX(Sheet1!AM$79:AM$88),0,1) -> 1 | AK12: =IF(Sheet1!AN86=MAX(Sheet1!AN$79:AN$88),0,1) -> 1 | ... BA12: =IF(Sheet1!BD86=MAX(Sheet1!BD$79:BD$88),0,1) -> 1
A13: G 09 | B13: PLTU 3 | C13: =Sheet1!BQ87-Sheet1!CR87 -> 0 | D13: =Sheet1!BR87-Sheet1!CS87 -> 0 | E13: =Sheet1!BS87-Sheet1!CT87 -> 0 | F13: =Sheet1!BT87-Sheet1!CU87 -> 0 | G13: =Sheet1!BU87-Sheet1!CV87 -> 0 | H13: =Sheet1!BV87-Sheet1!CW87 -> 0 | I13: =Sheet1!BW87-Sheet1!CX87 -> 0 | J13: =Sheet1!BX87-Sheet1!CY87 -> 0 | ... Z13: =Sheet1!CN87-Sheet1!DO87 -> 0 | AB13: G 09 | AC13: PLTU 3 | AD13: =IF(Sheet1!AG87=MAX(Sheet1!AG$79:AG$88),0,1) -> 1 | AE13: =IF(Sheet1!AH87=MAX(Sheet1!AH$79:AH$88),0,1) -> 1 | AF13: =IF(Sheet1!AI87=MAX(Sheet1!AI$79:AI$88),0,1) -> 1 | AG13: =IF(Sheet1!AJ87=MAX(Sheet1!AJ$79:AJ$88),0,1) -> 1 | AH13: =IF(Sheet1!AK87=MAX(Sheet1!AK$79:AK$88),0,1) -> 1 | AI13: =IF(Sheet1!AL87=MAX(Sheet1!AL$79:AL$88),0,1) -> 0 | AJ13: =IF(Sheet1!AM87=MAX(Sheet1!AM$79:AM$88),0,1) -> 0 | AK13: =IF(Sheet1!AN87=MAX(Sheet1!AN$79:AN$88),0,1) -> 0 | ... BA13: =IF(Sheet1!BD87=MAX(Sheet1!BD$79:BD$88),0,1) -> 1
A14: G 10 | B14: PLTU 4 | C14: =Sheet1!BQ88-Sheet1!CR88 -> 0 | D14: =Sheet1!BR88-Sheet1!CS88 -> 0 | E14: =Sheet1!BS88-Sheet1!CT88 -> 0 | F14: =Sheet1!BT88-Sheet1!CU88 -> 0 | G14: =Sheet1!BU88-Sheet1!CV88 -> 0 | H14: =Sheet1!BV88-Sheet1!CW88 -> 0 | I14: =Sheet1!BW88-Sheet1!CX88 -> 0 | J14: =Sheet1!BX88-Sheet1!CY88 -> 0 | ... Z14: =Sheet1!CN88-Sheet1!DO88 -> 0 | AB14: G 10 | AC14: PLTU 4 | AD14: =IF(Sheet1!AG88=MAX(Sheet1!AG$79:AG$88),0,1) -> 1 | AE14: =IF(Sheet1!AH88=MAX(Sheet1!AH$79:AH$88),0,1) -> 1 | AF14: =IF(Sheet1!AI88=MAX(Sheet1!AI$79:AI$88),0,1) -> 1 | AG14: =IF(Sheet1!AJ88=MAX(Sheet1!AJ$79:AJ$88),0,1) -> 1 | AH14: =IF(Sheet1!AK88=MAX(Sheet1!AK$79:AK$88),0,1) -> 1 | AI14: =IF(Sheet1!AL88=MAX(Sheet1!AL$79:AL$88),0,1) -> 1 | AJ14: =IF(Sheet1!AM88=MAX(Sheet1!AM$79:AM$88),0,1) -> 1 | AK14: =IF(Sheet1!AN88=MAX(Sheet1!AN$79:AN$88),0,1) -> 1 | ... BA14: =IF(Sheet1!BD88=MAX(Sheet1!BD$79:BD$88),0,1) -> 1
A18: #6 | consInit + consUC + consMUTMDT + consBasicRamp + consSRContingency + consSteadyPrimFreq
A19: Spinning - Reserve | AB19: Status Contingency (0, jika lepas) | BC19: Reserve
A20: Gen | C20: Hour | AB20: Gen | AD20: Hour | BC20: Spinning Reserve | BD20: Hour
C21: 1 | D21: 2 | E21: 3 | F21: 4 | G21: 5 | H21: 6 | I21: 7 | J21: 8 | K21: 9 | L21: 10 | M21: 11 | N21: 12 | O21: 13 | P21: 14 | Q21: 15 | R21: 16 | S21: 17 | T21: 18 | U21: 19 | V21: 20 | W21: 21 | X21: 22 | Y21: 23 | Z21: 24 | AD21: 1 | AE21: 2 | AF21: 3 | AG21: 4 | AH21: 5 | AI21: 6 | AJ21: 7 | AK21: 8 | AL21: 9 | AM21: 10 | AN21: 11 | AO21: 12 | AP21: 13 | AQ21: 14 | AR21: 15 | AS21: 16 | AT21: 17 | AU21: 18 | AV21: 19 | AW21: 20 | AX21: 21 | AY21: 22 | AZ21: 23 | BA21: 24 | BD21: 1 | BE21: 2 | BF21: 3 | BG21: 4 | BH21: 5 | BI21: 6 | BJ21: 7 | BK21: 8 | BL21: 9 | BM21: 10 | BN21: 11 | BO21: 12 | BP21: 13 | BQ21: 14 | BR21: 15 | BS21: 16 | BT21: 17 | BU21: 18 | BV21: 19 | BW21: 20 | BX21: 21 | BY21: 22 | BZ21: 23 | CA21: 24
A22: G 01 | B22: PLTU 1 | C22: =Sheet1!BQ97-Sheet1!CR97 -> 0 | D22: =Sheet1!BR97-Sheet1!CS97 -> 0 | E22: =Sheet1!BS97-Sheet1!CT97 -> 0 | F22: =Sheet1!BT97-Sheet1!CU97 -> 0 | G22: =Sheet1!BU97-Sheet1!CV97 -> -2.2737368e-13 | H22: =Sheet1!BV97-Sheet1!CW97 -> 0 | I22: =Sheet1!BW97-Sheet1!CX97 -> -1.7053026e-13 | J22: =Sheet1!BX97-Sheet1!CY97 -> -1.3500312e-13 | ... Z22: =Sheet1!CN97-Sheet1!DO97 -> 0 | AB22: G 01 | AC22: PLTU 1 | AD22: =IF(Sheet1!AG97=MAX(Sheet1!AG$97:AG$106),0,1) -> 0 | AE22: =IF(Sheet1!AH97=MAX(Sheet1!AH$97:AH$106),0,1) -> 0 | AF22: =IF(Sheet1!AI97=MAX(Sheet1!AI$97:AI$106),0,1) -> 0 | AG22: =IF(Sheet1!AJ97=MAX(Sheet1!AJ$97:AJ$106),0,1) -> 0 | AH22: =IF(Sheet1!AK97=MAX(Sheet1!AK$97:AK$106),0,1) -> 0 | AI22: =IF(Sheet1!AL97=MAX(Sheet1!AL$97:AL$106),0,1) -> 0 | AJ22: =IF(Sheet1!AM97=MAX(Sheet1!AM$97:AM$106),0,1) -> 0 | AK22: =IF(Sheet1!AN97=MAX(Sheet1!AN$97:AN$106),0,1) -> 0 | ... BA22: =IF(Sheet1!BD97=MAX(Sheet1!BD$97:BD$106),0,1) -> 0 | BC22: Ploss | BD22: =MAX(Sheet1!AG97:AG106) -> 1141.8 | BE22: =MAX(Sheet1!AH97:AH106) -> 1060.8 | BF22: =MAX(Sheet1!AI97:AI106) -> 940.8 | BG22: =MAX(Sheet1!AJ97:AJ106) -> 1060.8 | BH22: =MAX(Sheet1!AK97:AK106) -> 946.0788 | BI22: =MAX(Sheet1!AL97:AL106) -> 967.8 | BJ22: =MAX(Sheet1!AM97:AM106) -> 1087.8 | BK22: =MAX(Sheet1!AN97:AN106) -> 1141.8 | ... CA22: =MAX(Sheet1!BD97:BD106) -> 967.8
A23: G 02 | B23: PLTGU 1 | C23: =Sheet1!BQ98-Sheet1!CR98 -> 560 | D23: =Sheet1!BR98-Sheet1!CS98 -> 509.83155 | E23: =Sheet1!BS98-Sheet1!CT98 -> 560 | F23: =Sheet1!BT98-Sheet1!CU98 -> 560 | G23: =Sheet1!BU98-Sheet1!CV98 -> 565.04988 | H23: =Sheet1!BV98-Sheet1!CW98 -> 560 | I23: =Sheet1!BW98-Sheet1!CX98 -> 560 | J23: =Sheet1!BX98-Sheet1!CY98 -> 560 | ... Z23: =Sheet1!CN98-Sheet1!DO98 -> 560 | AB23: G 02 | AC23: PLTGU 1 | AD23: =IF(Sheet1!AG98=MAX(Sheet1!AG$97:AG$106),0,1) -> 1 | AE23: =IF(Sheet1!AH98=MAX(Sheet1!AH$97:AH$106),0,1) -> 1 | AF23: =IF(Sheet1!AI98=MAX(Sheet1!AI$97:AI$106),0,1) -> 1 | AG23: =IF(Sheet1!AJ98=MAX(Sheet1!AJ$97:AJ$106),0,1) -> 1 | AH23: =IF(Sheet1!AK98=MAX(Sheet1!AK$97:AK$106),0,1) -> 1 | AI23: =IF(Sheet1!AL98=MAX(Sheet1!AL$97:AL$106),0,1) -> 1 | AJ23: =IF(Sheet1!AM98=MAX(Sheet1!AM$97:AM$106),0,1) -> 1 | AK23: =IF(Sheet1!AN98=MAX(Sheet1!AN$97:AN$106),0,1) -> 1 | ... BA23: =IF(Sheet1!BD98=MAX(Sheet1!BD$97:BD$106),0,1) -> 1 | BC23: Spinning Total | BD23: =SUM(Sheet1!BQ97:BQ106) -> 2659.3232 | BE23: =SUM(Sheet1!BR97:BR106) -> 2711.8315 | BF23: =SUM(Sheet1!BS97:BS106) -> 2795.7982 | BG23: =SUM(Sheet1!BT97:BT106) -> 2875.6166 | BH23: =SUM(Sheet1!BU97:BU106) -> 2875.6166 | BI23: =SUM(Sheet1!BV97:BV106) -> 2673.479 | BJ23: =SUM(Sheet1!BW97:BW106) -> 2611.9396 | BK23: =SUM(Sheet1!BX97:BX106) -> 2660.3081 | ... CA23: =SUM(Sheet1!CN97:CN106) -> 2388.7435
A24: G 03 | B24: PLTU 2 | C24: =Sheet1!BQ99-Sheet1!CR99 -> 55.2 | D24: =Sheet1!BR99-Sheet1!CS99 -> 0 | E24: =Sheet1!BS99-Sheet1!CT99 -> 0 | F24: =Sheet1!BT99-Sheet1!CU99 -> 113.61663 | G24: =Sheet1!BU99-Sheet1!CV99 -> 24.245058 | H24: =Sheet1!BV99-Sheet1!CW99 -> 0 | I24: =Sheet1!BW99-Sheet1!CX99 -> 0 | J24: =Sheet1!BX99-Sheet1!CY99 -> 0 | ... Z24: =Sheet1!CN99-Sheet1!DO99 -> 0 | AB24: G 03 | AC24: PLTU 2 | AD24: =IF(Sheet1!AG99=MAX(Sheet1!AG$97:AG$106),0,1) -> 1 | AE24: =IF(Sheet1!AH99=MAX(Sheet1!AH$97:AH$106),0,1) -> 1 | AF24: =IF(Sheet1!AI99=MAX(Sheet1!AI$97:AI$106),0,1) -> 1 | AG24: =IF(Sheet1!AJ99=MAX(Sheet1!AJ$97:AJ$106),0,1) -> 1 | AH24: =IF(Sheet1!AK99=MAX(Sheet1!AK$97:AK$106),0,1) -> 1 | AI24: =IF(Sheet1!AL99=MAX(Sheet1!AL$97:AL$106),0,1) -> 1 | AJ24: =IF(Sheet1!AM99=MAX(Sheet1!AM$97:AM$106),0,1) -> 1 | AK24: =IF(Sheet1!AN99=MAX(Sheet1!AN$97:AN$106),0,1) -> 1 | ... BA24: =IF(Sheet1!BD99=MAX(Sheet1!BD$97:BD$106),0,1) -> 1 | BC24: Spinning Back Up | BD24: =SUMPRODUCT(Sheet1!BQ97:BQ106,Sheet5!AD22:AD31) -> 2625.1232 | BE24: =SUMPRODUCT(Sheet1!BR97:BR106,Sheet5!AE22:AE31) -> 2596.6315 | BF24: =SUMPRODUCT(Sheet1!BS97:BS106,Sheet5!AF22:AF31) -> 2560.5982 | BG24: =SUMPRODUCT(Sheet1!BT97:BT106,Sheet5!AG22:AG31) -> 2760.4166 | BH24: =SUMPRODUCT(Sheet1!BU97:BU106,Sheet5!AH22:AH31) -> 2645.6954 | BI24: =SUMPRODUCT(Sheet1!BV97:BV106,Sheet5!AI22:AI31) -> 2465.279 | BJ24: =SUMPRODUCT(Sheet1!BW97:BW106,Sheet5!AJ22:AJ31) -> 2523.7396 | BK24: =SUMPRODUCT(Sheet1!BX97:BX106,Sheet5!AK22:AK31) -> 2626.1081 | ... CA24: =SUMPRODUCT(Sheet1!CN97:CN106,Sheet5!BA22:BA31) -> 2180.5435
A25: G 04 | B25: PLTG 1 | C25: =Sheet1!BQ100-Sheet1!CR100 -> 0 | D25: =Sheet1!BR100-Sheet1!CS100 -> 0 | E25: =Sheet1!BS100-Sheet1!CT100 -> 0 | F25: =Sheet1!BT100-Sheet1!CU100 -> 0 | G25: =Sheet1!BU100-Sheet1!CV100 -> 0 | H25: =Sheet1!BV100-Sheet1!CW100 -> 0 | I25: =Sheet1!BW100-Sheet1!CX100 -> 0 | J25: =Sheet1!BX100-Sheet1!CY100 -> 0 | ... Z25: =Sheet1!CN100-Sheet1!DO100 -> 0 | AB25: G 04 | AC25: PLTG 1 | AD25: =IF(Sheet1!AG100=MAX(Sheet1!AG$97:AG$106),0,1) -> 1 | AE25: =IF(Sheet1!AH100=MAX(Sheet1!AH$97:AH$106),0,1) -> 1 | AF25: =IF(Sheet1!AI100=MAX(Sheet1!AI$97:AI$106),0,1) -> 1 | AG25: =IF(Sheet1!AJ100=MAX(Sheet1!AJ$97:AJ$106),0,1) -> 1 | AH25: =IF(Sheet1!AK100=MAX(Sheet1!AK$97:AK$106),0,1) -> 1 | AI25: =IF(Sheet1!AL100=MAX(Sheet1!AL$97:AL$106),0,1) -> 1 | AJ25: =IF(Sheet1!AM100=MAX(Sheet1!AM$97:AM$106),0,1) -> 1 | AK25: =IF(Sheet1!AN100=MAX(Sheet1!AN$97:AN$106),0,1) -> 1 | ... BA25: =IF(Sheet1!BD100=MAX(Sheet1!BD$97:BD$106),0,1) -> 1 | BC25: Primary Total | BD25: =SUM(Sheet1!CR97:CR106) -> 1176 | BE25: =SUM(Sheet1!CS97:CS106) -> 1176 | BF25: =SUM(Sheet1!CT97:CT106) -> 1209.7982 | BG25: =SUM(Sheet1!CU97:CU106) -> 1176 | BH25: =SUM(Sheet1!CV97:CV106) -> 1176 | BI25: =SUM(Sheet1!CW97:CW106) -> 1176 | BJ25: =SUM(Sheet1!CX97:CX106) -> 1176 | BK25: =SUM(Sheet1!CY97:CY106) -> 1176 | ... CA25: =SUM(Sheet1!DO97:DO106) -> 1176
A26: G 05 | B26: PLTG 2 | C26: =Sheet1!BQ101-Sheet1!CR101 -> 0 | D26: =Sheet1!BR101-Sheet1!CS101 -> 0 | E26: =Sheet1!BS101-Sheet1!CT101 -> 0 | F26: =Sheet1!BT101-Sheet1!CU101 -> 0 | G26: =Sheet1!BU101-Sheet1!CV101 -> 0 | H26: =Sheet1!BV101-Sheet1!CW101 -> 0 | I26: =Sheet1!BW101-Sheet1!CX101 -> 0 | J26: =Sheet1!BX101-Sheet1!CY101 -> 0 | ... Z26: =Sheet1!CN101-Sheet1!DO101 -> 0 | AB26: G 05 | AC26: PLTG 2 | AD26: =IF(Sheet1!AG101=MAX(Sheet1!AG$97:AG$106),0,1) -> 1 | AE26: =IF(Sheet1!AH101=MAX(Sheet1!AH$97:AH$106),0,1) -> 1 | AF26: =IF(Sheet1!AI101=MAX(Sheet1!AI$97:AI$106),0,1) -> 1 | AG26: =IF(Sheet1!AJ101=MAX(Sheet1!AJ$97:AJ$106),0,1) -> 1 | AH26: =IF(Sheet1!AK101=MAX(Sheet1!AK$97:AK$106),0,1) -> 1 | AI26: =IF(Sheet1!AL101=MAX(Sheet1!AL$97:AL$106),0,1) -> 1 | AJ26: =IF(Sheet1!AM101=MAX(Sheet1!AM$97:AM$106),0,1) -> 1 | AK26: =IF(Sheet1!AN101=MAX(Sheet1!AN$97:AN$106),0,1) -> 1 | ... BA26: =IF(Sheet1!BD101=MAX(Sheet1!BD$97:BD$106),0,1) -> 1 | BC26: Primary Back Up | BD26: =SUMPRODUCT(Sheet1!CR97:CR106,Sheet5!AD22:AD31) -> 1141.8 | BE26: =SUMPRODUCT(Sheet1!CS97:CS106,Sheet5!AE22:AE31) -> 1060.8 | BF26: =SUMPRODUCT(Sheet1!CT97:CT106,Sheet5!AF22:AF31) -> 974.59821 | BG26: =SUMPRODUCT(Sheet1!CU97:CU106,Sheet5!AG22:AG31) -> 1060.8 | BH26: =SUMPRODUCT(Sheet1!CV97:CV106,Sheet5!AH22:AH31) -> 946.0788 | BI26: =SUMPRODUCT(Sheet1!CW97:CW106,Sheet5!AI22:AI31) -> 967.8 | BJ26: =SUMPRODUCT(Sheet1!CX97:CX106,Sheet5!AJ22:AJ31) -> 1087.8 | BK26: =SUMPRODUCT(Sheet1!CY97:CY106,Sheet5!AK22:AK31) -> 1141.8 | ... CA26: =SUMPRODUCT(Sheet1!DO97:DO106,Sheet5!BA22:BA31) -> 967.8
A27: G 06 | B27: PLTGU 2 | C27: =Sheet1!BQ102-Sheet1!CR102 -> 432.12317 | D27: =Sheet1!BR102-Sheet1!CS102 -> 626 | E27: =Sheet1!BS102-Sheet1!CT102 -> 626 | F27: =Sheet1!BT102-Sheet1!CU102 -> 626 | G27: =Sheet1!BU102-Sheet1!CV102 -> 630.91521 | H27: =Sheet1!BV102-Sheet1!CW102 -> 537.47898 | I27: =Sheet1!BW102-Sheet1!CX102 -> 475.93959 | J27: =Sheet1!BX102-Sheet1!CY102 -> 524.30806 | ... Z27: =Sheet1!CN102-Sheet1!DO102 -> 626 | AB27: G 06 | AC27: PLTGU 2 | AD27: =IF(Sheet1!AG102=MAX(Sheet1!AG$97:AG$106),0,1) -> 1 | AE27: =IF(Sheet1!AH102=MAX(Sheet1!AH$97:AH$106),0,1) -> 1 | AF27: =IF(Sheet1!AI102=MAX(Sheet1!AI$97:AI$106),0,1) -> 1 | AG27: =IF(Sheet1!AJ102=MAX(Sheet1!AJ$97:AJ$106),0,1) -> 1 | AH27: =IF(Sheet1!AK102=MAX(Sheet1!AK$97:AK$106),0,1) -> 1 | AI27: =IF(Sheet1!AL102=MAX(Sheet1!AL$97:AL$106),0,1) -> 1 | AJ27: =IF(Sheet1!AM102=MAX(Sheet1!AM$97:AM$106),0,1) -> 1 | AK27: =IF(Sheet1!AN102=MAX(Sheet1!AN$97:AN$106),0,1) -> 1 | ... BA27: =IF(Sheet1!BD102=MAX(Sheet1!BD$97:BD$106),0,1) -> 1
A28: G 07 | B28: PLTGU 3 | C28: =Sheet1!BQ103-Sheet1!CR103 -> 400 | D28: =Sheet1!BR103-Sheet1!CS103 -> 400 | E28: =Sheet1!BS103-Sheet1!CT103 -> 400 | F28: =Sheet1!BT103-Sheet1!CU103 -> 400 | G28: =Sheet1!BU103-Sheet1!CV103 -> 403.63591 | H28: =Sheet1!BV103-Sheet1!CW103 -> 400 | I28: =Sheet1!BW103-Sheet1!CX103 -> 400 | J28: =Sheet1!BX103-Sheet1!CY103 -> 400 | ... Z28: =Sheet1!CN103-Sheet1!DO103 -> 26.743498 | AB28: G 07 | AC28: PLTGU 3 | AD28: =IF(Sheet1!AG103=MAX(Sheet1!AG$97:AG$106),0,1) -> 1 | AE28: =IF(Sheet1!AH103=MAX(Sheet1!AH$97:AH$106),0,1) -> 1 | AF28: =IF(Sheet1!AI103=MAX(Sheet1!AI$97:AI$106),0,1) -> 1 | AG28: =IF(Sheet1!AJ103=MAX(Sheet1!AJ$97:AJ$106),0,1) -> 1 | AH28: =IF(Sheet1!AK103=MAX(Sheet1!AK$97:AK$106),0,1) -> 1 | AI28: =IF(Sheet1!AL103=MAX(Sheet1!AL$97:AL$106),0,1) -> 1 | AJ28: =IF(Sheet1!AM103=MAX(Sheet1!AM$97:AM$106),0,1) -> 1 | AK28: =IF(Sheet1!AN103=MAX(Sheet1!AN$97:AN$106),0,1) -> 1 | ... BA28: =IF(Sheet1!BD103=MAX(Sheet1!BD$97:BD$106),0,1) -> 1
A29: G 08 | B29: PLTGU 4 | C29: =Sheet1!BQ104-Sheet1!CR104 -> 0 | D29: =Sheet1!BR104-Sheet1!CS104 -> 0 | E29: =Sheet1!BS104-Sheet1!CT104 -> 0 | F29: =Sheet1!BT104-Sheet1!CU104 -> 0 | G29: =Sheet1!BU104-Sheet1!CV104 -> 0 | H29: =Sheet1!BV104-Sheet1!CW104 -> 0 | I29: =Sheet1!BW104-Sheet1!CX104 -> 0 | J29: =Sheet1!BX104-Sheet1!CY104 -> 0 | ... Z29: =Sheet1!CN104-Sheet1!DO104 -> 0 | AB29: G 08 | AC29: PLTGU 4 | AD29: =IF(Sheet1!AG104=MAX(Sheet1!AG$97:AG$106),0,1) -> 1 | AE29: =IF(Sheet1!AH104=MAX(Sheet1!AH$97:AH$106),0,1) -> 1 | AF29: =IF(Sheet1!AI104=MAX(Sheet1!AI$97:AI$106),0,1) -> 1 | AG29: =IF(Sheet1!AJ104=MAX(Sheet1!AJ$97:AJ$106),0,1) -> 1 | AH29: =IF(Sheet1!AK104=MAX(Sheet1!AK$97:AK$106),0,1) -> 1 | AI29: =IF(Sheet1!AL104=MAX(Sheet1!AL$97:AL$106),0,1) -> 1 | AJ29: =IF(Sheet1!AM104=MAX(Sheet1!AM$97:AM$106),0,1) -> 1 | AK29: =IF(Sheet1!AN104=MAX(Sheet1!AN$97:AN$106),0,1) -> 1 | ... BA29: =IF(Sheet1!BD104=MAX(Sheet1!BD$97:BD$106),0,1) -> 1
A30: G 09 | B30: PLTU 3 | C30: =Sheet1!BQ105-Sheet1!CR105 -> 36 | D30: =Sheet1!BR105-Sheet1!CS105 -> 0 | E30: =Sheet1!BS105-Sheet1!CT105 -> 0 | F30: =Sheet1!BT105-Sheet1!CU105 -> 0 | G30: =Sheet1!BU105-Sheet1!CV105 -> 0 | H30: =Sheet1!BV105-Sheet1!CW105 -> 0 | I30: =Sheet1!BW105-Sheet1!CX105 -> 0 | J30: =Sheet1!BX105-Sheet1!CY105 -> 0 | ... Z30: =Sheet1!CN105-Sheet1!DO105 -> 0 | AB30: G 09 | AC30: PLTU 3 | AD30: =IF(Sheet1!AG105=MAX(Sheet1!AG$97:AG$106),0,1) -> 1 | AE30: =IF(Sheet1!AH105=MAX(Sheet1!AH$97:AH$106),0,1) -> 1 | AF30: =IF(Sheet1!AI105=MAX(Sheet1!AI$97:AI$106),0,1) -> 1 | AG30: =IF(Sheet1!AJ105=MAX(Sheet1!AJ$97:AJ$106),0,1) -> 1 | AH30: =IF(Sheet1!AK105=MAX(Sheet1!AK$97:AK$106),0,1) -> 1 | AI30: =IF(Sheet1!AL105=MAX(Sheet1!AL$97:AL$106),0,1) -> 1 | AJ30: =IF(Sheet1!AM105=MAX(Sheet1!AM$97:AM$106),0,1) -> 1 | AK30: =IF(Sheet1!AN105=MAX(Sheet1!AN$97:AN$106),0,1) -> 1 | ... BA30: =IF(Sheet1!BD105=MAX(Sheet1!BD$97:BD$106),0,1) -> 1
A31: G 10 | B31: PLTU 4 | C31: =Sheet1!BQ106-Sheet1!CR106 -> 0 | D31: =Sheet1!BR106-Sheet1!CS106 -> 0 | E31: =Sheet1!BS106-Sheet1!CT106 -> 0 | F31: =Sheet1!BT106-Sheet1!CU106 -> 0 | G31: =Sheet1!BU106-Sheet1!CV106 -> 75.770574 | H31: =Sheet1!BV106-Sheet1!CW106 -> 0 | I31: =Sheet1!BW106-Sheet1!CX106 -> 0 | J31: =Sheet1!BX106-Sheet1!CY106 -> 0 | ... Z31: =Sheet1!CN106-Sheet1!DO106 -> 0 | AB31: G 10 | AC31: PLTU 4 | AD31: =IF(Sheet1!AG106=MAX(Sheet1!AG$97:AG$106),0,1) -> 1 | AE31: =IF(Sheet1!AH106=MAX(Sheet1!AH$97:AH$106),0,1) -> 1 | AF31: =IF(Sheet1!AI106=MAX(Sheet1!AI$97:AI$106),0,1) -> 1 | AG31: =IF(Sheet1!AJ106=MAX(Sheet1!AJ$97:AJ$106),0,1) -> 1 | AH31: =IF(Sheet1!AK106=MAX(Sheet1!AK$97:AK$106),0,1) -> 1 | AI31: =IF(Sheet1!AL106=MAX(Sheet1!AL$97:AL$106),0,1) -> 1 | AJ31: =IF(Sheet1!AM106=MAX(Sheet1!AM$97:AM$106),0,1) -> 1 | AK31: =IF(Sheet1!AN106=MAX(Sheet1!AN$97:AN$106),0,1) -> 1 | ... BA31: =IF(Sheet1!BD106=MAX(Sheet1!BD$97:BD$106),0,1) -> 1

Sheet Sheet2
B1: #1 | C1: #2 | D1: #3 | E1: #4 | F1: #5 | G1: #6 | H1: #7
A2: 1 | B2: 505.5 | C2: 505.5 | D2: 651.3 | E2: 651.3 | F2: 992.94 | G2: 853.8 | H2: 708
A3: 2 | B3: 505.5 | C3: 505.5 | D3: 651.3 | E3: 651.3 | F3: 853.8 | G3: 853.8 | H3: 708
A4: 3 | B4: 505.5 | C4: 505.5 | D4: 651.3 | E4: 651.3 | F4: 853.8 | G4: 853.8 | H4: 708
A5: 4 | B5: 505.5 | C5: 505.5 | D5: 651.3 | E5: 651.3 | F5: 853.8 | G5: 853.8 | H5: 708
A6: 5 | B6: 505.5 | C6: 505.5 | D6: 651.3 | E6: 651.3 | F6: 853.8 | G6: 853.8 | H6: 708
A7: 6 | B7: 505.5 | C7: 505.5 | D7: 651.3 | E7: 651.3 | F7: 853.8 | G7: 853.8 | H7: 708
A8: 7 | B8: 505.5 | C8: 505.5 | D8: 651.3 | E8: 651.3 | F8: 853.8 | G8: 853.8 | H8: 708
A9: 8 | B9: 505.5 | C9: 505.5 | D9: 651.3 | E9: 651.3 | F9: 853.8 | G9: 853.8 | H9: 708
A10: 9 | B10: 505.5 | C10: 505.5 | D10: 651.3 | E10: 651.3 | F10: 853.8 | G10: 853.8 | H10: 708
A11: 10 | B11: 505.5 | C11: 505.5 | D11: 651.3 | E11: 790.44 | F11: 853.8 | G11: 853.8 | H11: 708
A12: 11 | B12: 518.46 | C12: 521.1 | D12: 651.3 | E12: 790.44 | F12: 853.8 | G12: 853.8 | H12: 723.6
A13: 12 | B13: 518.46 | C13: 521.1 | D13: 651.3 | E13: 790.44 | F13: 853.8 | G13: 853.8 | H13: 723.6
... A25: 24 | B25: 505.5 | C25: 505.5 | D25: 505.5 | E25: 651.3 | F25: 708 | G25: 853.8 | H25: 708

Sheet Gen
A1: Basic UC
A2: Unit | B2: Type | C2: Pmin | D2: Pmax | E2: a | F2: b ($/MW) | G2: c ($/h) | H2: SU_Cost ($) | I2: SD_Cost ($) | J2: Ramp_Up (MW) | K2: Ramp_Down (MW) | L2: Min_Up (h) | M2: Min_Down (h) | O2: FreeGovernor | P2: PFR_Fraction | Q2: Tg
A3: G1 | B3: PLTU 1 | C3: 627 | D3: 1176 | E3: 0 | F3: 26.08931 | G3: 3594.858 | H3: 58800 | I3: 0 | J3: 120 | K3: 120 | L3: 23 | M3: 23 | O3: 1 | P3: 0.15 | Q3: 2.25
A4: G2 | B4: PLTGU 1 | C4: 340 | D4: 1125 | E4: 0 | F4: 51.250827 | G4: 3825.0617 | H4: 90000 | I4: 0 | J4: 300 | K4: 300 | L4: 2 | M4: 12 | O4: 1 | P4: 0.2 | Q4: 1.5
A5: G3 | B5: PLTU 2 | C5: 600 | D5: 969 | E5: 0 | F5: 26.08931 | G5: 3440.0555 | H5: 48450 | I5: 0 | J5: 120 | K5: 120 | L5: 23 | M5: 23 | O5: 1 | P5: 0.2 | Q5: 1
A6: G4 | B6: PLTG 1 | C6: 85 | D6: 130 | E6: 0 | F6: 89.128422 | G6: 1662.9237 | H6: 3120 | I6: 0 | J6: 480 | K6: 480 | L6: 12 | M6: 10 | O6: 1 | P6: 0.15 | Q6: 1.75
A7: G5 | B7: PLTG 2 | C7: 66 | D7: 108 | E7: 0 | F7: 89.128422 | G7: 1291.2113 | H7: 2592 | I7: 0 | J7: 480 | K7: 480 | L7: 2 | M7: 2 | O7: 1 | P7: 0.2 | Q7: 1.25
A8: G6 | B8: PLTGU 2 | C8: 250 | D8: 1095 | E8: 0 | F8: 51.250827 | G8: 2812.5454 | H8: 87600 | I8: 0 | J8: 300 | K8: 300 | L8: 2 | M8: 2 | O8: 1 | P8: 0.2 | Q8: 1
A9: G7 | B9: PLTGU 3 | C9: 248 | D9: 810 | E9: 0 | F9: 51.250827 | G9: 2790.045 | H9: 64800 | I9: 0 | J9: 300 | K9: 300 | L9: 23 | M9: 23 | O9: 1 | P9: 0.2 | Q9: 1
A10: G8 | B10: PLTGU 4 | C10: 347.85 | D10: 773 | E10: 0 | F10: 51.250827 | G10: 3913.3756 | H10: 61840 | I10: 0 | J10: 300 | K10: 300 | L10: 1 | M10: 2 | O10: 1 | P10: 0.2 | Q10: 1
A11: G9 | B11: PLTU 3 | C11: 540 | D11: 870 | E11: 0 | F11: 26.08931 | G11: 3096.05 | H11: 43500 | I11: 0 | J11: 120 | K11: 120 | L11: 1 | M11: 3 | O11: 1 | P11: 0.2 | Q11: 1
